<?xml version="1.0" encoding="utf-8" ?>
<!-- =================================================================================== -->
<!-- |    This document was autogenerated by xacro from /home/sakthi/ws_moveit/src/hand/hand_description/urdf/hand.xacro | -->
<!-- |    EDITING THIS FILE BY HAND IS NOT RECOMMENDED                                 | -->
<!-- =================================================================================== -->
<robot name="hand">
    <material name="silver_default">
        <color rgba="0.700 0.700 0.700 1.000" />
    </material>
    <material name="steel_satin">
        <color rgba="0.6274509803921569 0.6274509803921569 0.6274509803921569 1.0" />
    </material>
    <transmission name="t_mcp_pitch_tran">
        <type>transmission_interface/SimpleTransmission</type>
        <joint name="t_mcp_pitch">
            <hardwareInterface>hardware_interface/EffortJointInterface</hardwareInterface>
        </joint>
        <actuator name="t_mcp_pitch_actr">
            <hardwareInterface>hardware_interface/EffortJointInterface</hardwareInterface>
            <mechanicalReduction>1</mechanicalReduction>
        </actuator>
    </transmission>
    <transmission name="t_mcp_yaw_tran">
        <type>transmission_interface/SimpleTransmission</type>
        <joint name="t_mcp_yaw">
            <hardwareInterface>hardware_interface/EffortJointInterface</hardwareInterface>
        </joint>
        <actuator name="t_mcp_yaw_actr">
            <hardwareInterface>hardware_interface/EffortJointInterface</hardwareInterface>
            <mechanicalReduction>1</mechanicalReduction>
        </actuator>
    </transmission>
    <transmission name="t_pip_pitch_tran">
        <type>transmission_interface/SimpleTransmission</type>
        <joint name="t_pip_pitch">
            <hardwareInterface>hardware_interface/EffortJointInterface</hardwareInterface>
        </joint>
        <actuator name="t_pip_pitch_actr">
            <hardwareInterface>hardware_interface/EffortJointInterface</hardwareInterface>
            <mechanicalReduction>1</mechanicalReduction>
        </actuator>
    </transmission>
    <transmission name="i_mcp_yaw_tran">
        <type>transmission_interface/SimpleTransmission</type>
        <joint name="i_mcp_yaw">
            <hardwareInterface>hardware_interface/EffortJointInterface</hardwareInterface>
        </joint>
        <actuator name="i_mcp_yaw_actr">
            <hardwareInterface>hardware_interface/EffortJointInterface</hardwareInterface>
            <mechanicalReduction>1</mechanicalReduction>
        </actuator>
    </transmission>
    <transmission name="i_mcp_pitch_tran">
        <type>transmission_interface/SimpleTransmission</type>
        <joint name="i_mcp_pitch">
            <hardwareInterface>hardware_interface/EffortJointInterface</hardwareInterface>
        </joint>
        <actuator name="i_mcp_pitch_actr">
            <hardwareInterface>hardware_interface/EffortJointInterface</hardwareInterface>
            <mechanicalReduction>1</mechanicalReduction>
        </actuator>
    </transmission>
    <transmission name="i_pip_pitch_tran">
        <type>transmission_interface/SimpleTransmission</type>
        <joint name="i_pip_pitch">
            <hardwareInterface>hardware_interface/EffortJointInterface</hardwareInterface>
        </joint>
        <actuator name="i_pip_pitch_actr">
            <hardwareInterface>hardware_interface/EffortJointInterface</hardwareInterface>
            <mechanicalReduction>1</mechanicalReduction>
        </actuator>
    </transmission>
    <transmission name="i_dip_pitch_tran">
        <type>transmission_interface/SimpleTransmission</type>
        <joint name="i_dip_pitch">
            <hardwareInterface>hardware_interface/EffortJointInterface</hardwareInterface>
        </joint>
        <actuator name="i_dip_pitch_actr">
            <hardwareInterface>hardware_interface/EffortJointInterface</hardwareInterface>
            <mechanicalReduction>1</mechanicalReduction>
        </actuator>
    </transmission>
    <transmission name="m_mcp_yaw_tran">
        <type>transmission_interface/SimpleTransmission</type>
        <joint name="m_mcp_yaw">
            <hardwareInterface>hardware_interface/EffortJointInterface</hardwareInterface>
        </joint>
        <actuator name="m_mcp_yaw_actr">
            <hardwareInterface>hardware_interface/EffortJointInterface</hardwareInterface>
            <mechanicalReduction>1</mechanicalReduction>
        </actuator>
    </transmission>
    <transmission name="m_mcp_pitch_tran">
        <type>transmission_interface/SimpleTransmission</type>
        <joint name="m_mcp_pitch">
            <hardwareInterface>hardware_interface/EffortJointInterface</hardwareInterface>
        </joint>
        <actuator name="m_mcp_pitch_actr">
            <hardwareInterface>hardware_interface/EffortJointInterface</hardwareInterface>
            <mechanicalReduction>1</mechanicalReduction>
        </actuator>
    </transmission>
    <transmission name="m_pip_pitch_tran">
        <type>transmission_interface/SimpleTransmission</type>
        <joint name="m_pip_pitch">
            <hardwareInterface>hardware_interface/EffortJointInterface</hardwareInterface>
        </joint>
        <actuator name="m_pip_pitch_actr">
            <hardwareInterface>hardware_interface/EffortJointInterface</hardwareInterface>
            <mechanicalReduction>1</mechanicalReduction>
        </actuator>
    </transmission>
    <transmission name="m_dip_pitch_tran">
        <type>transmission_interface/SimpleTransmission</type>
        <joint name="m_dip_pitch">
            <hardwareInterface>hardware_interface/EffortJointInterface</hardwareInterface>
        </joint>
        <actuator name="m_dip_pitch_actr">
            <hardwareInterface>hardware_interface/EffortJointInterface</hardwareInterface>
            <mechanicalReduction>1</mechanicalReduction>
        </actuator>
    </transmission>
    <transmission name="r_mcp_yaw_tran">
        <type>transmission_interface/SimpleTransmission</type>
        <joint name="r_mcp_yaw">
            <hardwareInterface>hardware_interface/EffortJointInterface</hardwareInterface>
        </joint>
        <actuator name="r_mcp_yaw_actr">
            <hardwareInterface>hardware_interface/EffortJointInterface</hardwareInterface>
            <mechanicalReduction>1</mechanicalReduction>
        </actuator>
    </transmission>
    <transmission name="r_mcp_pitch_tran">
        <type>transmission_interface/SimpleTransmission</type>
        <joint name="r_mcp_pitch">
            <hardwareInterface>hardware_interface/EffortJointInterface</hardwareInterface>
        </joint>
        <actuator name="r_mcp_pitch_actr">
            <hardwareInterface>hardware_interface/EffortJointInterface</hardwareInterface>
            <mechanicalReduction>1</mechanicalReduction>
        </actuator>
    </transmission>
    <transmission name="r_pip_pitch_tran">
        <type>transmission_interface/SimpleTransmission</type>
        <joint name="r_pip_pitch">
            <hardwareInterface>hardware_interface/EffortJointInterface</hardwareInterface>
        </joint>
        <actuator name="r_pip_pitch_actr">
            <hardwareInterface>hardware_interface/EffortJointInterface</hardwareInterface>
            <mechanicalReduction>1</mechanicalReduction>
        </actuator>
    </transmission>
    <transmission name="r_dip_pitch_tran">
        <type>transmission_interface/SimpleTransmission</type>
        <joint name="r_dip_pitch">
            <hardwareInterface>hardware_interface/EffortJointInterface</hardwareInterface>
        </joint>
        <actuator name="r_dip_pitch_actr">
            <hardwareInterface>hardware_interface/EffortJointInterface</hardwareInterface>
            <mechanicalReduction>1</mechanicalReduction>
        </actuator>
    </transmission>
    <transmission name="s_mcp_yaw_tran">
        <type>transmission_interface/SimpleTransmission</type>
        <joint name="s_mcp_yaw">
            <hardwareInterface>hardware_interface/EffortJointInterface</hardwareInterface>
        </joint>
        <actuator name="s_mcp_yaw_actr">
            <hardwareInterface>hardware_interface/EffortJointInterface</hardwareInterface>
            <mechanicalReduction>1</mechanicalReduction>
        </actuator>
    </transmission>
    <transmission name="s_mcp_pitch_tran">
        <type>transmission_interface/SimpleTransmission</type>
        <joint name="s_mcp_pitch">
            <hardwareInterface>hardware_interface/EffortJointInterface</hardwareInterface>
        </joint>
        <actuator name="s_mcp_pitch_actr">
            <hardwareInterface>hardware_interface/EffortJointInterface</hardwareInterface>
            <mechanicalReduction>1</mechanicalReduction>
        </actuator>
    </transmission>
    <transmission name="s_pip_pitch_tran">
        <type>transmission_interface/SimpleTransmission</type>
        <joint name="s_pip_pitch">
            <hardwareInterface>hardware_interface/EffortJointInterface</hardwareInterface>
        </joint>
        <actuator name="s_pip_pitch_actr">
            <hardwareInterface>hardware_interface/EffortJointInterface</hardwareInterface>
            <mechanicalReduction>1</mechanicalReduction>
        </actuator>
    </transmission>
    <transmission name="s_dip_pitch_tran">
        <type>transmission_interface/SimpleTransmission</type>
        <joint name="s_dip_pitch">
            <hardwareInterface>hardware_interface/EffortJointInterface</hardwareInterface>
        </joint>
        <actuator name="s_dip_pitch_actr">
            <hardwareInterface>hardware_interface/EffortJointInterface</hardwareInterface>
            <mechanicalReduction>1</mechanicalReduction>
        </actuator>
    </transmission>
    <gazebo>
        <plugin filename="libgazebo_ros_control.so" name="control" />
    </gazebo>
    <gazebo reference="base_link">
        <material>Gazebo/Silver</material>
        <mu1>0.2</mu1>
        <mu2>0.2</mu2>
        <selfCollide>true</selfCollide>
        <gravity>true</gravity>
    </gazebo>
    <gazebo reference="cmc_link_v4_1">
        <material>Gazebo/Silver</material>
        <mu1>0.2</mu1>
        <mu2>0.2</mu2>
        <selfCollide>true</selfCollide>
    </gazebo>
    <gazebo reference="t_connector_1_v1_1">
        <material>Gazebo/Silver</material>
        <mu1>0.2</mu1>
        <mu2>0.2</mu2>
        <selfCollide>true</selfCollide>
    </gazebo>
    <gazebo reference="t_mcp_v5_1">
        <material>Gazebo/Silver</material>
        <mu1>0.2</mu1>
        <mu2>0.2</mu2>
        <selfCollide>true</selfCollide>
    </gazebo>
    <gazebo reference="t_pip_link_v5_1">
        <material>Gazebo/Silver</material>
        <mu1>0.2</mu1>
        <mu2>0.2</mu2>
        <selfCollide>true</selfCollide>
    </gazebo>
    <gazebo reference="t_connector_2_v1_1">
        <material>Gazebo/Silver</material>
        <mu1>0.2</mu1>
        <mu2>0.2</mu2>
        <selfCollide>true</selfCollide>
    </gazebo>
    <gazebo reference="t_tip_v2_1">
        <material>Gazebo/Silver</material>
        <mu1>0.2</mu1>
        <mu2>0.2</mu2>
        <selfCollide>true</selfCollide>
    </gazebo>
    <gazebo reference="i_mcp_yaw_link_v1_1">
        <material>Gazebo/Silver</material>
        <mu1>0.2</mu1>
        <mu2>0.2</mu2>
        <selfCollide>true</selfCollide>
    </gazebo>
    <gazebo reference="i_mcp_pitch_link_v1_1">
        <material>Gazebo/Silver</material>
        <mu1>0.2</mu1>
        <mu2>0.2</mu2>
        <selfCollide>true</selfCollide>
    </gazebo>
    <gazebo reference="i_connector_1_v1_1">
        <material>Gazebo/Silver</material>
        <mu1>0.2</mu1>
        <mu2>0.2</mu2>
        <selfCollide>true</selfCollide>
    </gazebo>
    <gazebo reference="i_pip_pitch_link_v4_1">
        <material>Gazebo/Silver</material>
        <mu1>0.2</mu1>
        <mu2>0.2</mu2>
        <selfCollide>true</selfCollide>
    </gazebo>
    <gazebo reference="i_connector_2_v1_1">
        <material>Gazebo/Silver</material>
        <mu1>0.2</mu1>
        <mu2>0.2</mu2>
        <selfCollide>true</selfCollide>
    </gazebo>
    <gazebo reference="i_dip_link_v2_1">
        <material>Gazebo/Silver</material>
        <mu1>0.2</mu1>
        <mu2>0.2</mu2>
        <selfCollide>true</selfCollide>
    </gazebo>
    <gazebo reference="i_connector_3_v1_1">
        <material>Gazebo/Silver</material>
        <mu1>0.2</mu1>
        <mu2>0.2</mu2>
        <selfCollide>true</selfCollide>
    </gazebo>
    <gazebo reference="i_tip_link_v2_1">
        <material>Gazebo/Silver</material>
        <mu1>0.2</mu1>
        <mu2>0.2</mu2>
        <selfCollide>true</selfCollide>
    </gazebo>
    <gazebo reference="m_mcp_yaw_link_v1_1">
        <material>Gazebo/Silver</material>
        <mu1>0.2</mu1>
        <mu2>0.2</mu2>
        <selfCollide>true</selfCollide>
    </gazebo>
    <gazebo reference="m_mcp_pitch_link_v1_1">
        <material>Gazebo/Silver</material>
        <mu1>0.2</mu1>
        <mu2>0.2</mu2>
        <selfCollide>true</selfCollide>
    </gazebo>
    <gazebo reference="m_connector_1_v1_1">
        <material>Gazebo/Silver</material>
        <mu1>0.2</mu1>
        <mu2>0.2</mu2>
        <selfCollide>true</selfCollide>
    </gazebo>
    <gazebo reference="m_pip_pitch_link_v2_1">
        <material>Gazebo/Silver</material>
        <mu1>0.2</mu1>
        <mu2>0.2</mu2>
        <selfCollide>true</selfCollide>
    </gazebo>
    <gazebo reference="m_connector_2_v1_1">
        <material>Gazebo/Silver</material>
        <mu1>0.2</mu1>
        <mu2>0.2</mu2>
        <selfCollide>true</selfCollide>
    </gazebo>
    <gazebo reference="m_dip_link_v2_1">
        <material>Gazebo/Silver</material>
        <mu1>0.2</mu1>
        <mu2>0.2</mu2>
        <selfCollide>true</selfCollide>
    </gazebo>
    <gazebo reference="m_connector_3_v1_1">
        <material>Gazebo/Silver</material>
        <mu1>0.2</mu1>
        <mu2>0.2</mu2>
        <selfCollide>true</selfCollide>
    </gazebo>
    <gazebo reference="m_tip_link_v2_1">
        <material>Gazebo/Silver</material>
        <mu1>0.2</mu1>
        <mu2>0.2</mu2>
        <selfCollide>true</selfCollide>
    </gazebo>
    <gazebo reference="r_mcp_yaw_link_v1_1">
        <material>Gazebo/Silver</material>
        <mu1>0.2</mu1>
        <mu2>0.2</mu2>
        <selfCollide>true</selfCollide>
    </gazebo>
    <gazebo reference="r_mcp_pitch_link_v1_1">
        <material>Gazebo/Silver</material>
        <mu1>0.2</mu1>
        <mu2>0.2</mu2>
        <selfCollide>true</selfCollide>
    </gazebo>
    <gazebo reference="r_connector_1_v1_1">
        <material>Gazebo/Silver</material>
        <mu1>0.2</mu1>
        <mu2>0.2</mu2>
        <selfCollide>true</selfCollide>
    </gazebo>
    <gazebo reference="r_pip_pitch_link_v2_1">
        <material>Gazebo/Silver</material>
        <mu1>0.2</mu1>
        <mu2>0.2</mu2>
        <selfCollide>true</selfCollide>
    </gazebo>
    <gazebo reference="r_connector_2_v1_1">
        <material>Gazebo/Silver</material>
        <mu1>0.2</mu1>
        <mu2>0.2</mu2>
        <selfCollide>true</selfCollide>
    </gazebo>
    <gazebo reference="r_dip_link_v2_1">
        <material>Gazebo/Silver</material>
        <mu1>0.2</mu1>
        <mu2>0.2</mu2>
        <selfCollide>true</selfCollide>
    </gazebo>
    <gazebo reference="r_connector_3_v1_1">
        <material>Gazebo/Silver</material>
        <mu1>0.2</mu1>
        <mu2>0.2</mu2>
        <selfCollide>true</selfCollide>
    </gazebo>
    <gazebo reference="r_tip_link_v2_1">
        <material>Gazebo/Silver</material>
        <mu1>0.2</mu1>
        <mu2>0.2</mu2>
        <selfCollide>true</selfCollide>
    </gazebo>
    <gazebo reference="s_mcp_yaw_link_v1_1">
        <material>Gazebo/Silver</material>
        <mu1>0.2</mu1>
        <mu2>0.2</mu2>
        <selfCollide>true</selfCollide>
    </gazebo>
    <gazebo reference="s_mcp_pitch_link_v1_1">
        <material>Gazebo/Silver</material>
        <mu1>0.2</mu1>
        <mu2>0.2</mu2>
        <selfCollide>true</selfCollide>
    </gazebo>
    <gazebo reference="s_connector_1_v1_1">
        <material>Gazebo/Silver</material>
        <mu1>0.2</mu1>
        <mu2>0.2</mu2>
        <selfCollide>true</selfCollide>
    </gazebo>
    <gazebo reference="s_pip_pitch_link_v2_1">
        <material>Gazebo/Silver</material>
        <mu1>0.2</mu1>
        <mu2>0.2</mu2>
        <selfCollide>true</selfCollide>
    </gazebo>
    <gazebo reference="s_connector_2_v1_1">
        <material>Gazebo/Silver</material>
        <mu1>0.2</mu1>
        <mu2>0.2</mu2>
        <selfCollide>true</selfCollide>
    </gazebo>
    <gazebo reference="s_dip_link_v2_1">
        <material>Gazebo/Silver</material>
        <mu1>0.2</mu1>
        <mu2>0.2</mu2>
        <selfCollide>true</selfCollide>
    </gazebo>
    <gazebo reference="s_connector_3_v1_1">
        <material>Gazebo/Silver</material>
        <mu1>0.2</mu1>
        <mu2>0.2</mu2>
        <selfCollide>true</selfCollide>
    </gazebo>
    <gazebo reference="s_tip_link_v2_1">
        <material>Gazebo/Silver</material>
        <mu1>0.2</mu1>
        <mu2>0.2</mu2>
        <selfCollide>true</selfCollide>
    </gazebo>
    <link name="base_link">
        
<inertial>
            <origin rpy="0 0 0" xyz="-0.0018927237158815745 0.0009999999999999855 0.038608291526940605" />
            <mass value="0.1176699159976567" />
            <inertia ixx="6e-05" ixy="-0.0" ixz="7e-06" iyy="0.000149" iyz="0.0" izz="8.9e-05" />
        </inertial>

        <visual>
            <origin rpy="0 0 0" xyz="0 0 0" />
            <geometry>
                <mesh filename="package://hand_description/meshes/base_link.stl" scale="0.001 0.001 0.001" />
            </geometry>
            <material name="steel_satin" />
        </visual>
        <collision>
            <origin rpy="0 0 0" xyz="0 0 0" />
            <geometry>
                <mesh filename="package://hand_description/meshes/base_link.stl" scale="0.001 0.001 0.001" />
            </geometry>
        </collision>
    </link>
    <link name="cmc_link_v4_1">
        
<inertial>
            <origin rpy="0 0 0" xyz="-0.00048645427795625945 -0.004769447524329848 -6.493517695722872e-06" />
            <mass value="0.018416700517789007" />
            <inertia ixx="5e-06" ixy="-0.0" ixz="0.0" iyy="5e-06" iyz="-0.0" izz="0.0" />
        </inertial>

        <visual>
            <origin rpy="0 0 0" xyz="-0.039 0.0 -0.0225" />
            <geometry>
                <mesh filename="package://hand_description/meshes/cmc_link_v4_1.stl" scale="0.001 0.001 0.001" />
            </geometry>
            <material name="steel_satin" />
        </visual>
        <collision>
            <origin rpy="0 0 0" xyz="-0.039 0.0 -0.0225" />
            <geometry>
                <mesh filename="package://hand_description/meshes/cmc_link_v4_1.stl" scale="0.001 0.001 0.001" />
            </geometry>
        </collision>
    </link>
    <link name="t_connector_1_v1_1">
        
<inertial>
            <origin rpy="0 0 0" xyz="0.007499999970143861 -1.312864400526692e-11 -0.0012499999999999768" />
            <mass value="0.00374307805216622" />
            <inertia ixx="0.0" ixy="-0.0" ixz="-0.0" iyy="0.0" iyz="-0.0" izz="0.0" />
        </inertial>

        <visual>
            <origin rpy="0 0 0" xyz="-0.03825 0.007 -0.0225" />
            <geometry>
                <mesh filename="package://hand_description/meshes/t_connector_1_v1_1.stl" scale="0.001 0.001 0.001" />
            </geometry>
            <material name="steel_satin" />
        </visual>
        <collision>
            <origin rpy="0 0 0" xyz="-0.03825 0.007 -0.0225" />
            <geometry>
                <mesh filename="package://hand_description/meshes/t_connector_1_v1_1.stl" scale="0.001 0.001 0.001" />
            </geometry>
        </collision>
    </link>
    <link name="t_mcp_v5_1">
        
<inertial>
            <origin rpy="0 0 0" xyz="0.007807400362975329 0.002936289856962501 -0.00016613310844226098" />
            <mass value="0.03943050014537037" />
            <inertia ixx="1.1e-05" ixy="-0.0" ixz="0.0" iyy="1.3e-05" iyz="-0.0" izz="3e-06" />
        </inertial>

        <visual>
            <origin rpy="0 0 0" xyz="-0.05325 0.007 -0.0225" />
            <geometry>
                <mesh filename="package://hand_description/meshes/t_mcp_v5_1.stl" scale="0.001 0.001 0.001" />
            </geometry>
            <material name="steel_satin" />
        </visual>
        <collision>
            <origin rpy="0 0 0" xyz="-0.05325 0.007 -0.0225" />
            <geometry>
                <mesh filename="package://hand_description/meshes/t_mcp_v5_1.stl" scale="0.001 0.001 0.001" />
            </geometry>
        </collision>
    </link>
    <link name="t_pip_link_v5_1">
        
<inertial>
            <origin rpy="0 0 0" xyz="0.021556157971685322 -0.006243616814845158 2.555247680113837e-15" />
            <mass value="0.03216718051096679" />
            <inertia ixx="2e-06" ixy="1e-06" ixz="0.0" iyy="7e-06" iyz="-0.0" izz="6e-06" />
        </inertial>

        <visual>
            <origin rpy="0 0 0" xyz="-0.072947 0.004197 -0.014" />
            <geometry>
                <mesh filename="package://hand_description/meshes/t_pip_link_v5_1.stl" scale="0.001 0.001 0.001" />
            </geometry>
            <material name="steel_satin" />
        </visual>
        <collision>
            <origin rpy="0 0 0" xyz="-0.072947 0.004197 -0.014" />
            <geometry>
                <mesh filename="package://hand_description/meshes/t_pip_link_v5_1.stl" scale="0.001 0.001 0.001" />
            </geometry>
        </collision>
    </link>
    <link name="t_connector_2_v1_1">
        
<inertial>
            <origin rpy="0 0 0" xyz="0.00749969926025644 3.0084577047270744e-07 -0.0002499999999999603" />
            <mass value="0.00374307805216622" />
            <inertia ixx="0.0" ixy="0.0" ixz="-0.0" iyy="0.0" iyz="-0.0" izz="0.0" />
        </inertial>

        <visual>
            <origin rpy="0 0 0" xyz="-0.108947 0.013197 -0.014" />
            <geometry>
                <mesh filename="package://hand_description/meshes/t_connector_2_v1_1.stl" scale="0.001 0.001 0.001" />
            </geometry>
            <material name="steel_satin" />
        </visual>
        <collision>
            <origin rpy="0 0 0" xyz="-0.108947 0.013197 -0.014" />
            <geometry>
                <mesh filename="package://hand_description/meshes/t_connector_2_v1_1.stl" scale="0.001 0.001 0.001" />
            </geometry>
        </collision>
    </link>
    <link name="t_tip_v2_1">
        
<inertial>
            <origin rpy="0 0 0" xyz="0.001140939821871606 7.444969044555216e-08 0.0015000000000000378" />
            <mass value="0.011962131611831003" />
            <inertia ixx="1e-06" ixy="-0.0" ixz="0.0" iyy="1e-06" iyz="0.0" izz="0.0" />
        </inertial>

        <visual>
            <origin rpy="0 0 0" xyz="-0.123947 0.013197 -0.0125" />
            <geometry>
                <mesh filename="package://hand_description/meshes/t_tip_v2_1.stl" scale="0.001 0.001 0.001" />
            </geometry>
            <material name="steel_satin" />
        </visual>
        <collision>
            <origin rpy="0 0 0" xyz="-0.123947 0.013197 -0.0125" />
            <geometry>
                <mesh filename="package://hand_description/meshes/t_tip_v2_1.stl" scale="0.001 0.001 0.001" />
            </geometry>
        </collision>
    </link>
    <link name="i_mcp_yaw_link_v1_1">
        
<inertial>
            <origin rpy="0 0 0" xyz="-3.172462292866385e-14 -0.0012359787607253364 0.0005366094686043744" />
            <mass value="0.011430485562037091" />
            <inertia ixx="2e-06" ixy="-0.0" ixz="0.0" iyy="3e-06" iyz="0.0" izz="0.0" />
        </inertial>

        <visual>
            <origin rpy="0 0 0" xyz="-0.0195 0.0 -0.0225" />
            <geometry>
                <mesh filename="package://hand_description/meshes/i_mcp_yaw_link_v1_1.stl" scale="0.001 0.001 0.001" />
            </geometry>
            <material name="steel_satin" />
        </visual>
        <collision>
            <origin rpy="0 0 0" xyz="-0.0195 0.0 -0.0225" />
            <geometry>
                <mesh filename="package://hand_description/meshes/i_mcp_yaw_link_v1_1.stl" scale="0.001 0.001 0.001" />
            </geometry>
        </collision>
    </link>
    <link name="i_mcp_pitch_link_v1_1">
        
<inertial>
            <origin rpy="0 0 0" xyz="-4.586608870482678e-15 -0.005952105069446156 0.02420829596799528" />
            <mass value="0.026330610364773934" />
            <inertia ixx="5e-06" ixy="0.0" ixz="-0.0" iyy="6e-06" iyz="0.0" izz="2e-06" />
        </inertial>

        <visual>
            <origin rpy="0 0 0" xyz="-0.0195 0.002 -0.0405" />
            <geometry>
                <mesh filename="package://hand_description/meshes/i_mcp_pitch_link_v1_1.stl" scale="0.001 0.001 0.001" />
            </geometry>
            <material name="steel_satin" />
        </visual>
        <collision>
            <origin rpy="0 0 0" xyz="-0.0195 0.002 -0.0405" />
            <geometry>
                <mesh filename="package://hand_description/meshes/i_mcp_pitch_link_v1_1.stl" scale="0.001 0.001 0.001" />
            </geometry>
        </collision>
    </link>
    <link name="i_connector_1_v1_1">
        
<inertial>
            <origin rpy="0 0 0" xyz="0.0002500000000000002 -3.469446951953614e-17 0.007499999970251525" />
            <mass value="0.00374307805216622" />
            <inertia ixx="0.0" ixy="0.0" ixz="0.0" iyy="0.0" iyz="0.0" izz="0.0" />
        </inertial>

        <visual>
            <origin rpy="0 0 0" xyz="-0.0195 0.00925 -0.0815" />
            <geometry>
                <mesh filename="package://hand_description/meshes/i_connector_1_v1_1.stl" scale="0.001 0.001 0.001" />
            </geometry>
            <material name="steel_satin" />
        </visual>
        <collision>
            <origin rpy="0 0 0" xyz="-0.0195 0.00925 -0.0815" />
            <geometry>
                <mesh filename="package://hand_description/meshes/i_connector_1_v1_1.stl" scale="0.001 0.001 0.001" />
            </geometry>
        </collision>
    </link>
    <link name="i_pip_pitch_link_v4_1">
        
<inertial>
            <origin rpy="0 0 0" xyz="0.0010000000000000044 0.001096507521878223 0.018000000026317478" />
            <mass value="0.0314105238001653" />
            <inertia ixx="7e-06" ixy="-0.0" ixz="0.0" iyy="8e-06" iyz="-0.0" izz="2e-06" />
        </inertial>

        <visual>
            <origin rpy="0 0 0" xyz="-0.0185 0.00925 -0.0965" />
            <geometry>
                <mesh filename="package://hand_description/meshes/i_pip_pitch_link_v4_1.stl" scale="0.001 0.001 0.001" />
            </geometry>
            <material name="steel_satin" />
        </visual>
        <collision>
            <origin rpy="0 0 0" xyz="-0.0185 0.00925 -0.0965" />
            <geometry>
                <mesh filename="package://hand_description/meshes/i_pip_pitch_link_v4_1.stl" scale="0.001 0.001 0.001" />
            </geometry>
        </collision>
    </link>
    <link name="i_connector_2_v1_1">
        
<inertial>
            <origin rpy="0 0 0" xyz="0.0002500000000000002 -5.0306980803327406e-17 0.007499999970251553" />
            <mass value="0.00374307805216622" />
            <inertia ixx="0.0" ixy="-0.0" ixz="0.0" iyy="0.0" iyz="0.0" izz="0.0" />
        </inertial>

        <visual>
            <origin rpy="0 0 0" xyz="-0.0195 0.00925 -0.1325" />
            <geometry>
                <mesh filename="package://hand_description/meshes/i_connector_2_v1_1.stl" scale="0.001 0.001 0.001" />
            </geometry>
            <material name="steel_satin" />
        </visual>
        <collision>
            <origin rpy="0 0 0" xyz="-0.0195 0.00925 -0.1325" />
            <geometry>
                <mesh filename="package://hand_description/meshes/i_connector_2_v1_1.stl" scale="0.001 0.001 0.001" />
            </geometry>
        </collision>
    </link>
    <link name="i_dip_link_v2_1">
        
<inertial>
            <origin rpy="0 0 0" xyz="0.0010000228538777876 0.000633326000430515 0.005499983676315989" />
            <mass value="0.0165936992661325" />
            <inertia ixx="1e-06" ixy="0.0" ixz="0.0" iyy="1e-06" iyz="-0.0" izz="1e-06" />
        </inertial>

        <visual>
            <origin rpy="0 0 0" xyz="-0.0185 0.00925 -0.1475" />
            <geometry>
                <mesh filename="package://hand_description/meshes/i_dip_link_v2_1.stl" scale="0.001 0.001 0.001" />
            </geometry>
            <material name="steel_satin" />
        </visual>
        <collision>
            <origin rpy="0 0 0" xyz="-0.0185 0.00925 -0.1475" />
            <geometry>
                <mesh filename="package://hand_description/meshes/i_dip_link_v2_1.stl" scale="0.001 0.001 0.001" />
            </geometry>
        </collision>
    </link>
    <link name="i_connector_3_v1_1">
        
<inertial>
            <origin rpy="0 0 0" xyz="0.00025000000000001063 -7.632783294297951e-17 0.007499999970251553" />
            <mass value="0.00374307805216622" />
            <inertia ixx="0.0" ixy="-0.0" ixz="0.0" iyy="0.0" iyz="0.0" izz="0.0" />
        </inertial>

        <visual>
            <origin rpy="0 0 0" xyz="-0.0195 0.00925 -0.1585" />
            <geometry>
                <mesh filename="package://hand_description/meshes/i_connector_3_v1_1.stl" scale="0.001 0.001 0.001" />
            </geometry>
            <material name="steel_satin" />
        </visual>
        <collision>
            <origin rpy="0 0 0" xyz="-0.0195 0.00925 -0.1585" />
            <geometry>
                <mesh filename="package://hand_description/meshes/i_connector_3_v1_1.stl" scale="0.001 0.001 0.001" />
            </geometry>
        </collision>
    </link>
    <link name="i_tip_link_v2_1">
        
<inertial>
            <origin rpy="0 0 0" xyz="-0.0014999771461222076 0.0006333260004305029 0.005499983676315989" />
            <mass value="0.0165936992661325" />
            <inertia ixx="1e-06" ixy="0.0" ixz="0.0" iyy="1e-06" iyz="-0.0" izz="1e-06" />
        </inertial>

        <visual>
            <origin rpy="0 0 0" xyz="-0.021 0.00925 -0.1735" />
            <geometry>
                <mesh filename="package://hand_description/meshes/i_tip_link_v2_1.stl" scale="0.001 0.001 0.001" />
            </geometry>
            <material name="steel_satin" />
        </visual>
        <collision>
            <origin rpy="0 0 0" xyz="-0.021 0.00925 -0.1735" />
            <geometry>
                <mesh filename="package://hand_description/meshes/i_tip_link_v2_1.stl" scale="0.001 0.001 0.001" />
            </geometry>
        </collision>
    </link>
    <link name="m_mcp_yaw_link_v1_1">
        
<inertial>
            <origin rpy="0 0 0" xyz="1.7623359342441685e-14 -0.0012359787607253386 0.0005366094686043675" />
            <mass value="0.011430485562037091" />
            <inertia ixx="2e-06" ixy="0.0" ixz="-0.0" iyy="3e-06" iyz="0.0" izz="0.0" />
        </inertial>

        <visual>
            <origin rpy="0 0 0" xyz="-0.0 0.0 -0.0225" />
            <geometry>
                <mesh filename="package://hand_description/meshes/m_mcp_yaw_link_v1_1.stl" scale="0.001 0.001 0.001" />
            </geometry>
            <material name="steel_satin" />
        </visual>
        <collision>
            <origin rpy="0 0 0" xyz="-0.0 0.0 -0.0225" />
            <geometry>
                <mesh filename="package://hand_description/meshes/m_mcp_yaw_link_v1_1.stl" scale="0.001 0.001 0.001" />
            </geometry>
        </collision>
    </link>
    <link name="m_mcp_pitch_link_v1_1">
        
<inertial>
            <origin rpy="0 0 0" xyz="-4.5964789723509935e-15 -0.005952105069446156 0.024208295967995265" />
            <mass value="0.026330610364773934" />
            <inertia ixx="5e-06" ixy="0.0" ixz="-0.0" iyy="6e-06" iyz="0.0" izz="2e-06" />
        </inertial>

        <visual>
            <origin rpy="0 0 0" xyz="0.0 0.002 -0.0405" />
            <geometry>
                <mesh filename="package://hand_description/meshes/m_mcp_pitch_link_v1_1.stl" scale="0.001 0.001 0.001" />
            </geometry>
            <material name="steel_satin" />
        </visual>
        <collision>
            <origin rpy="0 0 0" xyz="0.0 0.002 -0.0405" />
            <geometry>
                <mesh filename="package://hand_description/meshes/m_mcp_pitch_link_v1_1.stl" scale="0.001 0.001 0.001" />
            </geometry>
        </collision>
    </link>
    <link name="m_connector_1_v1_1">
        
<inertial>
            <origin rpy="0 0 0" xyz="0.00024999999999998857 -1.0581813203458523e-16 0.007499999970251525" />
            <mass value="0.00374307805216622" />
            <inertia ixx="0.0" ixy="-0.0" ixz="-0.0" iyy="0.0" iyz="0.0" izz="0.0" />
        </inertial>

        <visual>
            <origin rpy="0 0 0" xyz="0.0 0.00925 -0.0815" />
            <geometry>
                <mesh filename="package://hand_description/meshes/m_connector_1_v1_1.stl" scale="0.001 0.001 0.001" />
            </geometry>
            <material name="steel_satin" />
        </visual>
        <collision>
            <origin rpy="0 0 0" xyz="0.0 0.00925 -0.0815" />
            <geometry>
                <mesh filename="package://hand_description/meshes/m_connector_1_v1_1.stl" scale="0.001 0.001 0.001" />
            </geometry>
        </collision>
    </link>
    <link name="m_pip_pitch_link_v2_1">
        
<inertial>
            <origin rpy="0 0 0" xyz="-0.0015000000000000044 0.0009393881307711328 0.018008883353284405" />
            <mass value="0.0314105238001653" />
            <inertia ixx="7e-06" ixy="-0.0" ixz="0.0" iyy="8e-06" iyz="0.0" izz="2e-06" />
        </inertial>

        <visual>
            <origin rpy="0 0 0" xyz="-0.0015 0.00925 -0.0965" />
            <geometry>
                <mesh filename="package://hand_description/meshes/m_pip_pitch_link_v2_1.stl" scale="0.001 0.001 0.001" />
            </geometry>
            <material name="steel_satin" />
        </visual>
        <collision>
            <origin rpy="0 0 0" xyz="-0.0015 0.00925 -0.0965" />
            <geometry>
                <mesh filename="package://hand_description/meshes/m_pip_pitch_link_v2_1.stl" scale="0.001 0.001 0.001" />
            </geometry>
        </collision>
    </link>
    <link name="m_connector_2_v1_1">
        
<inertial>
            <origin rpy="0 0 0" xyz="0.00025000000000000857 -6.560429417987179e-05 0.007499343623543014" />
            <mass value="0.00374307805216622" />
            <inertia ixx="0.0" ixy="-0.0" ixz="0.0" iyy="0.0" iyz="0.0" izz="0.0" />
        </inertial>

        <visual>
            <origin rpy="0 0 0" xyz="-0.0 0.009564 -0.132499" />
            <geometry>
                <mesh filename="package://hand_description/meshes/m_connector_2_v1_1.stl" scale="0.001 0.001 0.001" />
            </geometry>
            <material name="steel_satin" />
        </visual>
        <collision>
            <origin rpy="0 0 0" xyz="-0.0 0.009564 -0.132499" />
            <geometry>
                <mesh filename="package://hand_description/meshes/m_connector_2_v1_1.stl" scale="0.001 0.001 0.001" />
            </geometry>
        </collision>
    </link>
    <link name="m_dip_link_v2_1">
        
<inertial>
            <origin rpy="0 0 0" xyz="-0.0014999771461222094 0.0005852527718479845 0.005505359071886956" />
            <mass value="0.0165936992661325" />
            <inertia ixx="1e-06" ixy="0.0" ixz="0.0" iyy="1e-06" iyz="0.0" izz="1e-06" />
        </inertial>

        <visual>
            <origin rpy="0 0 0" xyz="-0.0015 0.009695 -0.147498" />
            <geometry>
                <mesh filename="package://hand_description/meshes/m_dip_link_v2_1.stl" scale="0.001 0.001 0.001" />
            </geometry>
            <material name="steel_satin" />
        </visual>
        <collision>
            <origin rpy="0 0 0" xyz="-0.0015 0.009695 -0.147498" />
            <geometry>
                <mesh filename="package://hand_description/meshes/m_dip_link_v2_1.stl" scale="0.001 0.001 0.001" />
            </geometry>
        </collision>
    </link>
    <link name="m_connector_3_v1_1">
        
<inertial>
            <origin rpy="0 0 0" xyz="0.0002499999999999933 -6.549421713753119e-05 0.00749935362321158" />
            <mass value="0.00374307805216622" />
            <inertia ixx="0.0" ixy="0.0" ixz="-0.0" iyy="0.0" iyz="0.0" izz="0.0" />
        </inertial>

        <visual>
            <origin rpy="0 0 0" xyz="-0.0 0.009791 -0.158498" />
            <geometry>
                <mesh filename="package://hand_description/meshes/m_connector_3_v1_1.stl" scale="0.001 0.001 0.001" />
            </geometry>
            <material name="steel_satin" />
        </visual>
        <collision>
            <origin rpy="0 0 0" xyz="-0.0 0.009791 -0.158498" />
            <geometry>
                <mesh filename="package://hand_description/meshes/m_connector_3_v1_1.stl" scale="0.001 0.001 0.001" />
            </geometry>
        </collision>
    </link>
    <link name="m_tip_link_v2_1">
        
<inertial>
            <origin rpy="0 0 0" xyz="-0.0014999771461222285 0.0005853628488903233 0.005505369071555438" />
            <mass value="0.0165936992661325" />
            <inertia ixx="1e-06" ixy="0.0" ixz="0.0" iyy="1e-06" iyz="0.0" izz="1e-06" />
        </inertial>

        <visual>
            <origin rpy="0 0 0" xyz="-0.0015 0.009922 -0.173497" />
            <geometry>
                <mesh filename="package://hand_description/meshes/m_tip_link_v2_1.stl" scale="0.001 0.001 0.001" />
            </geometry>
            <material name="steel_satin" />
        </visual>
        <collision>
            <origin rpy="0 0 0" xyz="-0.0015 0.009922 -0.173497" />
            <geometry>
                <mesh filename="package://hand_description/meshes/m_tip_link_v2_1.stl" scale="0.001 0.001 0.001" />
            </geometry>
        </collision>
    </link>
    <link name="r_mcp_yaw_link_v1_1">
        
<inertial>
            <origin rpy="0 0 0" xyz="-3.17280923756158e-14 -0.0012359787607253358 0.0005366094686043987" />
            <mass value="0.011430485562037091" />
            <inertia ixx="2e-06" ixy="-0.0" ixz="0.0" iyy="3e-06" iyz="0.0" izz="0.0" />
        </inertial>

        <visual>
            <origin rpy="0 0 0" xyz="0.0195 0.0 -0.0225" />
            <geometry>
                <mesh filename="package://hand_description/meshes/r_mcp_yaw_link_v1_1.stl" scale="0.001 0.001 0.001" />
            </geometry>
            <material name="steel_satin" />
        </visual>
        <collision>
            <origin rpy="0 0 0" xyz="0.0195 0.0 -0.0225" />
            <geometry>
                <mesh filename="package://hand_description/meshes/r_mcp_yaw_link_v1_1.stl" scale="0.001 0.001 0.001" />
            </geometry>
        </collision>
    </link>
    <link name="r_mcp_pitch_link_v1_1">
        
<inertial>
            <origin rpy="0 0 0" xyz="-4.593547764386585e-15 -0.005952105069446156 0.024208295967995307" />
            <mass value="0.026330610364773934" />
            <inertia ixx="5e-06" ixy="0.0" ixz="-0.0" iyy="6e-06" iyz="0.0" izz="2e-06" />
        </inertial>

        <visual>
            <origin rpy="0 0 0" xyz="0.0195 0.002 -0.0405" />
            <geometry>
                <mesh filename="package://hand_description/meshes/r_mcp_pitch_link_v1_1.stl" scale="0.001 0.001 0.001" />
            </geometry>
            <material name="steel_satin" />
        </visual>
        <collision>
            <origin rpy="0 0 0" xyz="0.0195 0.002 -0.0405" />
            <geometry>
                <mesh filename="package://hand_description/meshes/r_mcp_pitch_link_v1_1.stl" scale="0.001 0.001 0.001" />
            </geometry>
        </collision>
    </link>
    <link name="r_connector_1_v1_1">
        
<inertial>
            <origin rpy="0 0 0" xyz="0.00024999999999999675 -2.6020852139652106e-17 0.007499999970251553" />
            <mass value="0.00374307805216622" />
            <inertia ixx="0.0" ixy="-0.0" ixz="-0.0" iyy="0.0" iyz="0.0" izz="0.0" />
        </inertial>

        <visual>
            <origin rpy="0 0 0" xyz="0.0195 0.00925 -0.0815" />
            <geometry>
                <mesh filename="package://hand_description/meshes/r_connector_1_v1_1.stl" scale="0.001 0.001 0.001" />
            </geometry>
            <material name="steel_satin" />
        </visual>
        <collision>
            <origin rpy="0 0 0" xyz="0.0195 0.00925 -0.0815" />
            <geometry>
                <mesh filename="package://hand_description/meshes/r_connector_1_v1_1.stl" scale="0.001 0.001 0.001" />
            </geometry>
        </collision>
    </link>
    <link name="r_pip_pitch_link_v2_1">
        
<inertial>
            <origin rpy="0 0 0" xyz="-0.001500000000000029 0.00109650752187823 0.017999999914078108" />
            <mass value="0.0314105238001653" />
            <inertia ixx="7e-06" ixy="0.0" ixz="-0.0" iyy="8e-06" iyz="0.0" izz="2e-06" />
        </inertial>

        <visual>
            <origin rpy="0 0 0" xyz="0.018 0.00925 -0.0965" />
            <geometry>
                <mesh filename="package://hand_description/meshes/r_pip_pitch_link_v2_1.stl" scale="0.001 0.001 0.001" />
            </geometry>
            <material name="steel_satin" />
        </visual>
        <collision>
            <origin rpy="0 0 0" xyz="0.018 0.00925 -0.0965" />
            <geometry>
                <mesh filename="package://hand_description/meshes/r_pip_pitch_link_v2_1.stl" scale="0.001 0.001 0.001" />
            </geometry>
        </collision>
    </link>
    <link name="r_connector_2_v1_1">
        
<inertial>
            <origin rpy="0 0 0" xyz="0.0002499999999999343 -3.122502256758253e-17 0.0074999999702514974" />
            <mass value="0.00374307805216622" />
            <inertia ixx="0.0" ixy="-0.0" ixz="0.0" iyy="0.0" iyz="0.0" izz="0.0" />
        </inertial>

        <visual>
            <origin rpy="0 0 0" xyz="0.0195 0.00925 -0.1325" />
            <geometry>
                <mesh filename="package://hand_description/meshes/r_connector_2_v1_1.stl" scale="0.001 0.001 0.001" />
            </geometry>
            <material name="steel_satin" />
        </visual>
        <collision>
            <origin rpy="0 0 0" xyz="0.0195 0.00925 -0.1325" />
            <geometry>
                <mesh filename="package://hand_description/meshes/r_connector_2_v1_1.stl" scale="0.001 0.001 0.001" />
            </geometry>
        </collision>
    </link>
    <link name="r_dip_link_v2_1">
        
<inertial>
            <origin rpy="0 0 0" xyz="0.0010000228538776974 0.0006333260004305185 0.005499983676316045" />
            <mass value="0.0165936992661325" />
            <inertia ixx="1e-06" ixy="0.0" ixz="0.0" iyy="1e-06" iyz="-0.0" izz="1e-06" />
        </inertial>

        <visual>
            <origin rpy="0 0 0" xyz="0.0205 0.00925 -0.1475" />
            <geometry>
                <mesh filename="package://hand_description/meshes/r_dip_link_v2_1.stl" scale="0.001 0.001 0.001" />
            </geometry>
            <material name="steel_satin" />
        </visual>
        <collision>
            <origin rpy="0 0 0" xyz="0.0205 0.00925 -0.1475" />
            <geometry>
                <mesh filename="package://hand_description/meshes/r_dip_link_v2_1.stl" scale="0.001 0.001 0.001" />
            </geometry>
        </collision>
    </link>
    <link name="r_connector_3_v1_1">
        
<inertial>
            <origin rpy="0 0 0" xyz="0.00024999999999991 3.122502256758253e-17 0.0074999999702516085" />
            <mass value="0.00374307805216622" />
            <inertia ixx="0.0" ixy="0.0" ixz="0.0" iyy="0.0" iyz="0.0" izz="0.0" />
        </inertial>

        <visual>
            <origin rpy="0 0 0" xyz="0.0195 0.00925 -0.1585" />
            <geometry>
                <mesh filename="package://hand_description/meshes/r_connector_3_v1_1.stl" scale="0.001 0.001 0.001" />
            </geometry>
            <material name="steel_satin" />
        </visual>
        <collision>
            <origin rpy="0 0 0" xyz="0.0195 0.00925 -0.1585" />
            <geometry>
                <mesh filename="package://hand_description/meshes/r_connector_3_v1_1.stl" scale="0.001 0.001 0.001" />
            </geometry>
        </collision>
    </link>
    <link name="r_tip_link_v2_1">
        
<inertial>
            <origin rpy="0 0 0" xyz="0.0010000228538776766 0.000633326000430548 0.005499983676316017" />
            <mass value="0.0165936992661325" />
            <inertia ixx="1e-06" ixy="0.0" ixz="0.0" iyy="1e-06" iyz="-0.0" izz="1e-06" />
        </inertial>

        <visual>
            <origin rpy="0 0 0" xyz="0.0205 0.00925 -0.1735" />
            <geometry>
                <mesh filename="package://hand_description/meshes/r_tip_link_v2_1.stl" scale="0.001 0.001 0.001" />
            </geometry>
            <material name="steel_satin" />
        </visual>
        <collision>
            <origin rpy="0 0 0" xyz="0.0205 0.00925 -0.1735" />
            <geometry>
                <mesh filename="package://hand_description/meshes/r_tip_link_v2_1.stl" scale="0.001 0.001 0.001" />
            </geometry>
        </collision>
    </link>
    <link name="s_mcp_yaw_link_v1_1">
        
<inertial>
            <origin rpy="0 0 0" xyz="-3.1731561822567755e-14 -0.0012359787607253373 0.0005366094686043744" />
            <mass value="0.011430485562037091" />
            <inertia ixx="2e-06" ixy="-0.0" ixz="0.0" iyy="3e-06" iyz="0.0" izz="0.0" />
        </inertial>

        <visual>
            <origin rpy="0 0 0" xyz="0.039 0.0 -0.0225" />
            <geometry>
                <mesh filename="package://hand_description/meshes/s_mcp_yaw_link_v1_1.stl" scale="0.001 0.001 0.001" />
            </geometry>
            <material name="steel_satin" />
        </visual>
        <collision>
            <origin rpy="0 0 0" xyz="0.039 0.0 -0.0225" />
            <geometry>
                <mesh filename="package://hand_description/meshes/s_mcp_yaw_link_v1_1.stl" scale="0.001 0.001 0.001" />
            </geometry>
        </collision>
    </link>
    <link name="s_mcp_pitch_link_v1_1">
        
<inertial>
            <origin rpy="0 0 0" xyz="-4.5727310826748635e-15 -0.005952105069446158 0.024208295967995265" />
            <mass value="0.026330610364773934" />
            <inertia ixx="5e-06" ixy="0.0" ixz="-0.0" iyy="6e-06" iyz="0.0" izz="2e-06" />
        </inertial>

        <visual>
            <origin rpy="0 0 0" xyz="0.039 0.002 -0.0405" />
            <geometry>
                <mesh filename="package://hand_description/meshes/s_mcp_pitch_link_v1_1.stl" scale="0.001 0.001 0.001" />
            </geometry>
            <material name="steel_satin" />
        </visual>
        <collision>
            <origin rpy="0 0 0" xyz="0.039 0.002 -0.0405" />
            <geometry>
                <mesh filename="package://hand_description/meshes/s_mcp_pitch_link_v1_1.stl" scale="0.001 0.001 0.001" />
            </geometry>
        </collision>
    </link>
    <link name="s_connector_1_v1_1">
        
<inertial>
            <origin rpy="0 0 0" xyz="0.0002500000000000141 -3.9898639947466563e-17 0.007499999970143861" />
            <mass value="0.00374307805216622" />
            <inertia ixx="0.0" ixy="0.0" ixz="0.0" iyy="0.0" iyz="-0.0" izz="0.0" />
        </inertial>

        <visual>
            <origin rpy="0 0 0" xyz="0.039 0.00925 -0.0815" />
            <geometry>
                <mesh filename="package://hand_description/meshes/s_connector_1_v1_1.stl" scale="0.001 0.001 0.001" />
            </geometry>
            <material name="steel_satin" />
        </visual>
        <collision>
            <origin rpy="0 0 0" xyz="0.039 0.00925 -0.0815" />
            <geometry>
                <mesh filename="package://hand_description/meshes/s_connector_1_v1_1.stl" scale="0.001 0.001 0.001" />
            </geometry>
        </collision>
    </link>
    <link name="s_pip_pitch_link_v2_1">
        
<inertial>
            <origin rpy="0 0 0" xyz="0.0010000000000000009 0.0010965075218782126 0.018000000026317423" />
            <mass value="0.0314105238001653" />
            <inertia ixx="7e-06" ixy="0.0" ixz="-0.0" iyy="8e-06" iyz="-0.0" izz="2e-06" />
        </inertial>

        <visual>
            <origin rpy="0 0 0" xyz="0.04 0.00925 -0.0965" />
            <geometry>
                <mesh filename="package://hand_description/meshes/s_pip_pitch_link_v2_1.stl" scale="0.001 0.001 0.001" />
            </geometry>
            <material name="steel_satin" />
        </visual>
        <collision>
            <origin rpy="0 0 0" xyz="0.04 0.00925 -0.0965" />
            <geometry>
                <mesh filename="package://hand_description/meshes/s_pip_pitch_link_v2_1.stl" scale="0.001 0.001 0.001" />
            </geometry>
        </collision>
    </link>
    <link name="s_connector_2_v1_1">
        
<inertial>
            <origin rpy="0 0 0" xyz="0.00025000000000002104 -1.0408340855860843e-17 0.007499999970143834" />
            <mass value="0.00374307805216622" />
            <inertia ixx="0.0" ixy="0.0" ixz="0.0" iyy="0.0" iyz="-0.0" izz="0.0" />
        </inertial>

        <visual>
            <origin rpy="0 0 0" xyz="0.039 0.00925 -0.1325" />
            <geometry>
                <mesh filename="package://hand_description/meshes/s_connector_2_v1_1.stl" scale="0.001 0.001 0.001" />
            </geometry>
            <material name="steel_satin" />
        </visual>
        <collision>
            <origin rpy="0 0 0" xyz="0.039 0.00925 -0.1325" />
            <geometry>
                <mesh filename="package://hand_description/meshes/s_connector_2_v1_1.stl" scale="0.001 0.001 0.001" />
            </geometry>
        </collision>
    </link>
    <link name="s_dip_link_v2_1">
        
<inertial>
            <origin rpy="0 0 0" xyz="0.0010000228538777495 0.0006333260004305966 0.0054999836763159615" />
            <mass value="0.0165936992661325" />
            <inertia ixx="1e-06" ixy="0.0" ixz="0.0" iyy="1e-06" iyz="-0.0" izz="1e-06" />
        </inertial>

        <visual>
            <origin rpy="0 0 0" xyz="0.04 0.00925 -0.1475" />
            <geometry>
                <mesh filename="package://hand_description/meshes/s_dip_link_v2_1.stl" scale="0.001 0.001 0.001" />
            </geometry>
            <material name="steel_satin" />
        </visual>
        <collision>
            <origin rpy="0 0 0" xyz="0.04 0.00925 -0.1475" />
            <geometry>
                <mesh filename="package://hand_description/meshes/s_dip_link_v2_1.stl" scale="0.001 0.001 0.001" />
            </geometry>
        </collision>
    </link>
    <link name="s_connector_3_v1_1">
        
<inertial>
            <origin rpy="0 0 0" xyz="0.00025000000000005573 -5.898059818321144e-17 0.007499999970251581" />
            <mass value="0.00374307805216622" />
            <inertia ixx="0.0" ixy="-0.0" ixz="0.0" iyy="0.0" iyz="0.0" izz="0.0" />
        </inertial>

        <visual>
            <origin rpy="0 0 0" xyz="0.039 0.00925 -0.1585" />
            <geometry>
                <mesh filename="package://hand_description/meshes/s_connector_3_v1_1.stl" scale="0.001 0.001 0.001" />
            </geometry>
            <material name="steel_satin" />
        </visual>
        <collision>
            <origin rpy="0 0 0" xyz="0.039 0.00925 -0.1585" />
            <geometry>
                <mesh filename="package://hand_description/meshes/s_connector_3_v1_1.stl" scale="0.001 0.001 0.001" />
            </geometry>
        </collision>
    </link>
    <link name="s_tip_link_v2_1">
        
<inertial>
            <origin rpy="0 0 0" xyz="0.0010000228538778189 0.0006333260004305445 0.005499983676316045" />
            <mass value="0.0165936992661325" />
            <inertia ixx="1e-06" ixy="0.0" ixz="0.0" iyy="1e-06" iyz="-0.0" izz="1e-06" />
        </inertial>

        <visual>
            <origin rpy="0 0 0" xyz="0.04 0.00925 -0.1735" />
            <geometry>
                <mesh filename="package://hand_description/meshes/s_tip_link_v2_1.stl" scale="0.001 0.001 0.001" />
            </geometry>
            <material name="steel_satin" />
        </visual>
        <collision>
            <origin rpy="0 0 0" xyz="0.04 0.00925 -0.1735" />
            <geometry>
                <mesh filename="package://hand_description/meshes/s_tip_link_v2_1.stl" scale="0.001 0.001 0.001" />
            </geometry>
        </collision>
    </link>
    <joint name="Rigid1" type="fixed">
        <origin rpy="0 0 0" xyz="0.039 0.0 0.0225" />
        <parent link="base_link" />
        <child link="cmc_link_v4_1" />
    </joint>
    <joint name="t_mcp_pitch" type="continuous">
        <origin rpy="0 0 0" xyz="-0.00075 -0.007 0.0" />
        <parent link="cmc_link_v4_1" />
        <child link="t_connector_1_v1_1" />
        <axis xyz="0.0 0.0 -1.0" />
    </joint>
    <joint name="Rigid3" type="fixed">
        <origin rpy="0 0 0" xyz="0.015 0.0 0.0" />
        <parent link="t_connector_1_v1_1" />
        <child link="t_mcp_v5_1" />
    </joint>
    <joint name="t_mcp_yaw" type="continuous">
        <origin rpy="0 0 0" xyz="0.019697 0.002803 -0.0085" />
        <parent link="t_mcp_v5_1" />
        <child link="t_pip_link_v5_1" />
        <axis xyz="0.0 -1.0 -0.0" />
    </joint>
    <joint name="t_pip_pitch" type="continuous">
        <origin rpy="0 0 0" xyz="0.036 -0.009 0.0" />
        <parent link="t_pip_link_v5_1" />
        <child link="t_connector_2_v1_1" />
        <axis xyz="-0.0 0.0 -1.0" />
    </joint>
    <joint name="Rigid6" type="fixed">
        <origin rpy="0 0 0" xyz="0.015 0.0 -0.0015" />
        <parent link="t_connector_2_v1_1" />
        <child link="t_tip_v2_1" />
    </joint>
    <joint name="Rigid7" type="fixed">
        <origin rpy="0 0 0" xyz="0.0195 0.0 0.0225" />
        <parent link="base_link" />
        <child link="i_mcp_yaw_link_v1_1" />
    </joint>
    <joint name="i_mcp_yaw" type="continuous">
        <origin rpy="0 0 0" xyz="0.0 -0.002 0.018" />
        <parent link="i_mcp_yaw_link_v1_1" />
        <child link="i_mcp_pitch_link_v1_1" />
        <axis xyz="0.0 -1.0 -0.0" />
    </joint>
    <joint name="i_mcp_pitch" type="continuous">
        <origin rpy="0 0 0" xyz="0.0 -0.00725 0.041" />
        <parent link="i_mcp_pitch_link_v1_1" />
        <child link="i_connector_1_v1_1" />
        <axis xyz="-1.0 0.0 0.0" />
    </joint>
    <joint name="Rigid11" type="fixed">
        <origin rpy="0 0 0" xyz="-0.001 0.0 0.015" />
        <parent link="i_connector_1_v1_1" />
        <child link="i_pip_pitch_link_v4_1" />
    </joint>
    <joint name="i_pip_pitch" type="continuous">
        <origin rpy="0 0 0" xyz="0.001 0.0 0.036" />
        <parent link="i_pip_pitch_link_v4_1" />
        <child link="i_connector_2_v1_1" />
        <axis xyz="-1.0 0.0 0.0" />
    </joint>
    <joint name="Rigid16" type="fixed">
        <origin rpy="0 0 0" xyz="-0.001 0.0 0.015" />
        <parent link="i_connector_2_v1_1" />
        <child link="i_dip_link_v2_1" />
    </joint>
    <joint name="i_dip_pitch" type="continuous">
        <origin rpy="0 0 0" xyz="0.001 0.0 0.011" />
        <parent link="i_dip_link_v2_1" />
        <child link="i_connector_3_v1_1" />
        <axis xyz="1.0 -0.0 -0.0" />
    </joint>
    <joint name="Rigid18" type="fixed">
        <origin rpy="0 0 0" xyz="0.0015 0.0 0.015" />
        <parent link="i_connector_3_v1_1" />
        <child link="i_tip_link_v2_1" />
    </joint>
    <joint name="Rigid19" type="fixed">
        <origin rpy="0 0 0" xyz="0.0 0.0 0.0225" />
        <parent link="base_link" />
        <child link="m_mcp_yaw_link_v1_1" />
    </joint>
    <joint name="m_mcp_yaw" type="continuous">
        <origin rpy="0 0 0" xyz="-0.0 -0.002 0.018" />
        <parent link="m_mcp_yaw_link_v1_1" />
        <child link="m_mcp_pitch_link_v1_1" />
        <axis xyz="0.0 -1.0 -0.0" />
    </joint>
    <joint name="m_mcp_pitch" type="continuous">
        <origin rpy="0 0 0" xyz="0.0 -0.00725 0.041" />
        <parent link="m_mcp_pitch_link_v1_1" />
        <child link="m_connector_1_v1_1" />
        <axis xyz="-1.0 -0.0 -0.0" />
    </joint>
    <joint name="Rigid22" type="fixed">
        <origin rpy="0 0 0" xyz="0.0015 0.0 0.015" />
        <parent link="m_connector_1_v1_1" />
        <child link="m_pip_pitch_link_v2_1" />
    </joint>
    <joint name="m_pip_pitch" type="continuous">
        <origin rpy="0 0 0" xyz="-0.0015 -0.000314 0.035999" />
        <parent link="m_pip_pitch_link_v2_1" />
        <child link="m_connector_2_v1_1" />
        <axis xyz="-1.0 0.0 0.0" />
    </joint>
    <joint name="Rigid24" type="fixed">
        <origin rpy="0 0 0" xyz="0.0015 -0.000131 0.014999" />
        <parent link="m_connector_2_v1_1" />
        <child link="m_dip_link_v2_1" />
    </joint>
    <joint name="m_dip_pitch" type="continuous">
        <origin rpy="0 0 0" xyz="-0.0015 -9.6e-05 0.011" />
        <parent link="m_dip_link_v2_1" />
        <child link="m_connector_3_v1_1" />
        <axis xyz="1.0 -0.0 -0.0" />
    </joint>
    <joint name="Rigid26" type="fixed">
        <origin rpy="0 0 0" xyz="0.0015 -0.000131 0.014999" />
        <parent link="m_connector_3_v1_1" />
        <child link="m_tip_link_v2_1" />
    </joint>
    <joint name="Rigid27" type="fixed">
        <origin rpy="0 0 0" xyz="-0.0195 0.0 0.0225" />
        <parent link="base_link" />
        <child link="r_mcp_yaw_link_v1_1" />
    </joint>
    <joint name="r_mcp_yaw" type="continuous">
        <origin rpy="0 0 0" xyz="0.0 -0.002 0.018" />
        <parent link="r_mcp_yaw_link_v1_1" />
        <child link="r_mcp_pitch_link_v1_1" />
        <axis xyz="0.0 -1.0 -0.0" />
    </joint>
    <joint name="r_mcp_pitch" type="continuous">
        <origin rpy="0 0 0" xyz="0.0 -0.00725 0.041" />
        <parent link="r_mcp_pitch_link_v1_1" />
        <child link="r_connector_1_v1_1" />
        <axis xyz="-1.0 0.0 0.0" />
    </joint>
    <joint name="Rigid30" type="fixed">
        <origin rpy="0 0 0" xyz="0.0015 0.0 0.015" />
        <parent link="r_connector_1_v1_1" />
        <child link="r_pip_pitch_link_v2_1" />
    </joint>
    <joint name="r_pip_pitch" type="continuous">
        <origin rpy="0 0 0" xyz="-0.0015 0.0 0.036" />
        <parent link="r_pip_pitch_link_v2_1" />
        <child link="r_connector_2_v1_1" />
        <axis xyz="1.0 0.0 0.0" />
    </joint>
    <joint name="Rigid32" type="fixed">
        <origin rpy="0 0 0" xyz="-0.001 0.0 0.015" />
        <parent link="r_connector_2_v1_1" />
        <child link="r_dip_link_v2_1" />
    </joint>
    <joint name="r_dip_pitch" type="continuous">
        <origin rpy="0 0 0" xyz="0.001 0.0 0.011" />
        <parent link="r_dip_link_v2_1" />
        <child link="r_connector_3_v1_1" />
        <axis xyz="1.0 0.0 0.0" />
    </joint>
    <joint name="Rigid35" type="fixed">
        <origin rpy="0 0 0" xyz="-0.001 0.0 0.015" />
        <parent link="r_connector_3_v1_1" />
        <child link="r_tip_link_v2_1" />
    </joint>
    <joint name="Rigid36" type="fixed">
        <origin rpy="0 0 0" xyz="-0.039 0.0 0.0225" />
        <parent link="base_link" />
        <child link="s_mcp_yaw_link_v1_1" />
    </joint>
    <joint name="s_mcp_yaw" type="continuous">
        <origin rpy="0 0 0" xyz="0.0 -0.002 0.018" />
        <parent link="s_mcp_yaw_link_v1_1" />
        <child link="s_mcp_pitch_link_v1_1" />
        <axis xyz="-0.0 -1.0 -0.0" />
    </joint>
    <joint name="s_mcp_pitch" type="continuous">
        <origin rpy="0 0 0" xyz="0.0 -0.00725 0.041" />
        <parent link="s_mcp_pitch_link_v1_1" />
        <child link="s_connector_1_v1_1" />
        <axis xyz="-1.0 0.0 0.0" />
    </joint>
    <joint name="Rigid39" type="fixed">
        <origin rpy="0 0 0" xyz="-0.001 0.0 0.015" />
        <parent link="s_connector_1_v1_1" />
        <child link="s_pip_pitch_link_v2_1" />
    </joint>
    <joint name="s_pip_pitch" type="continuous">
        <origin rpy="0 0 0" xyz="0.001 0.0 0.036" />
        <parent link="s_pip_pitch_link_v2_1" />
        <child link="s_connector_2_v1_1" />
        <axis xyz="-1.0 -0.0 -0.0" />
    </joint>
    <joint name="Rigid41" type="fixed">
        <origin rpy="0 0 0" xyz="-0.001 0.0 0.015" />
        <parent link="s_connector_2_v1_1" />
        <child link="s_dip_link_v2_1" />
    </joint>
    <joint name="s_dip_pitch" type="continuous">
        <origin rpy="0 0 0" xyz="0.001 0.0 0.011" />
        <parent link="s_dip_link_v2_1" />
        <child link="s_connector_3_v1_1" />
        <axis xyz="1.0 -0.0 -0.0" />
    </joint>
    <joint name="Rigid43" type="fixed">
        <origin rpy="0 0 0" xyz="-0.001 0.0 0.015" />
        <parent link="s_connector_3_v1_1" />
        <child link="s_tip_link_v2_1" />
    </joint>
    <transmission name="trans_t_mcp_pitch">
        <type>transmission_interface/SimpleTransmission</type>
        <joint name="t_mcp_pitch">
            <hardwareInterface>hardware_interface/EffortJointInterface</hardwareInterface>
        </joint>
        <actuator name="t_mcp_pitch_motor">
            <hardwareInterface>hardware_interface/EffortJointInterface</hardwareInterface>
            <mechanicalReduction>1</mechanicalReduction>
        </actuator>
    </transmission>
    <transmission name="trans_t_mcp_yaw">
        <type>transmission_interface/SimpleTransmission</type>
        <joint name="t_mcp_yaw">
            <hardwareInterface>hardware_interface/EffortJointInterface</hardwareInterface>
        </joint>
        <actuator name="t_mcp_yaw_motor">
            <hardwareInterface>hardware_interface/EffortJointInterface</hardwareInterface>
            <mechanicalReduction>1</mechanicalReduction>
        </actuator>
    </transmission>
    <transmission name="trans_t_pip_pitch">
        <type>transmission_interface/SimpleTransmission</type>
        <joint name="t_pip_pitch">
            <hardwareInterface>hardware_interface/EffortJointInterface</hardwareInterface>
        </joint>
        <actuator name="t_pip_pitch_motor">
            <hardwareInterface>hardware_interface/EffortJointInterface</hardwareInterface>
            <mechanicalReduction>1</mechanicalReduction>
        </actuator>
    </transmission>
    <transmission name="trans_i_mcp_yaw">
        <type>transmission_interface/SimpleTransmission</type>
        <joint name="i_mcp_yaw">
            <hardwareInterface>hardware_interface/EffortJointInterface</hardwareInterface>
        </joint>
        <actuator name="i_mcp_yaw_motor">
            <hardwareInterface>hardware_interface/EffortJointInterface</hardwareInterface>
            <mechanicalReduction>1</mechanicalReduction>
        </actuator>
    </transmission>
    <transmission name="trans_i_mcp_pitch">
        <type>transmission_interface/SimpleTransmission</type>
        <joint name="i_mcp_pitch">
            <hardwareInterface>hardware_interface/EffortJointInterface</hardwareInterface>
        </joint>
        <actuator name="i_mcp_pitch_motor">
            <hardwareInterface>hardware_interface/EffortJointInterface</hardwareInterface>
            <mechanicalReduction>1</mechanicalReduction>
        </actuator>
    </transmission>
    <transmission name="trans_i_pip_pitch">
        <type>transmission_interface/SimpleTransmission</type>
        <joint name="i_pip_pitch">
            <hardwareInterface>hardware_interface/EffortJointInterface</hardwareInterface>
        </joint>
        <actuator name="i_pip_pitch_motor">
            <hardwareInterface>hardware_interface/EffortJointInterface</hardwareInterface>
            <mechanicalReduction>1</mechanicalReduction>
        </actuator>
    </transmission>
    <transmission name="trans_i_dip_pitch">
        <type>transmission_interface/SimpleTransmission</type>
        <joint name="i_dip_pitch">
            <hardwareInterface>hardware_interface/EffortJointInterface</hardwareInterface>
        </joint>
        <actuator name="i_dip_pitch_motor">
            <hardwareInterface>hardware_interface/EffortJointInterface</hardwareInterface>
            <mechanicalReduction>1</mechanicalReduction>
        </actuator>
    </transmission>
    <transmission name="trans_m_mcp_yaw">
        <type>transmission_interface/SimpleTransmission</type>
        <joint name="m_mcp_yaw">
            <hardwareInterface>hardware_interface/EffortJointInterface</hardwareInterface>
        </joint>
        <actuator name="m_mcp_yaw_motor">
            <hardwareInterface>hardware_interface/EffortJointInterface</hardwareInterface>
            <mechanicalReduction>1</mechanicalReduction>
        </actuator>
    </transmission>
    <transmission name="trans_m_mcp_pitch">
        <type>transmission_interface/SimpleTransmission</type>
        <joint name="m_mcp_pitch">
            <hardwareInterface>hardware_interface/EffortJointInterface</hardwareInterface>
        </joint>
        <actuator name="m_mcp_pitch_motor">
            <hardwareInterface>hardware_interface/EffortJointInterface</hardwareInterface>
            <mechanicalReduction>1</mechanicalReduction>
        </actuator>
    </transmission>
    <transmission name="trans_m_pip_pitch">
        <type>transmission_interface/SimpleTransmission</type>
        <joint name="m_pip_pitch">
            <hardwareInterface>hardware_interface/EffortJointInterface</hardwareInterface>
        </joint>
        <actuator name="m_pip_pitch_motor">
            <hardwareInterface>hardware_interface/EffortJointInterface</hardwareInterface>
            <mechanicalReduction>1</mechanicalReduction>
        </actuator>
    </transmission>
    <transmission name="trans_m_dip_pitch">
        <type>transmission_interface/SimpleTransmission</type>
        <joint name="m_dip_pitch">
            <hardwareInterface>hardware_interface/EffortJointInterface</hardwareInterface>
        </joint>
        <actuator name="m_dip_pitch_motor">
            <hardwareInterface>hardware_interface/EffortJointInterface</hardwareInterface>
            <mechanicalReduction>1</mechanicalReduction>
        </actuator>
    </transmission>
    <transmission name="trans_r_mcp_yaw">
        <type>transmission_interface/SimpleTransmission</type>
        <joint name="r_mcp_yaw">
            <hardwareInterface>hardware_interface/EffortJointInterface</hardwareInterface>
        </joint>
        <actuator name="r_mcp_yaw_motor">
            <hardwareInterface>hardware_interface/EffortJointInterface</hardwareInterface>
            <mechanicalReduction>1</mechanicalReduction>
        </actuator>
    </transmission>
    <transmission name="trans_r_mcp_pitch">
        <type>transmission_interface/SimpleTransmission</type>
        <joint name="r_mcp_pitch">
            <hardwareInterface>hardware_interface/EffortJointInterface</hardwareInterface>
        </joint>
        <actuator name="r_mcp_pitch_motor">
            <hardwareInterface>hardware_interface/EffortJointInterface</hardwareInterface>
            <mechanicalReduction>1</mechanicalReduction>
        </actuator>
    </transmission>
    <transmission name="trans_r_pip_pitch">
        <type>transmission_interface/SimpleTransmission</type>
        <joint name="r_pip_pitch">
            <hardwareInterface>hardware_interface/EffortJointInterface</hardwareInterface>
        </joint>
        <actuator name="r_pip_pitch_motor">
            <hardwareInterface>hardware_interface/EffortJointInterface</hardwareInterface>
            <mechanicalReduction>1</mechanicalReduction>
        </actuator>
    </transmission>
    <transmission name="trans_r_dip_pitch">
        <type>transmission_interface/SimpleTransmission</type>
        <joint name="r_dip_pitch">
            <hardwareInterface>hardware_interface/EffortJointInterface</hardwareInterface>
        </joint>
        <actuator name="r_dip_pitch_motor">
            <hardwareInterface>hardware_interface/EffortJointInterface</hardwareInterface>
            <mechanicalReduction>1</mechanicalReduction>
        </actuator>
    </transmission>
    <transmission name="trans_s_mcp_yaw">
        <type>transmission_interface/SimpleTransmission</type>
        <joint name="s_mcp_yaw">
            <hardwareInterface>hardware_interface/EffortJointInterface</hardwareInterface>
        </joint>
        <actuator name="s_mcp_yaw_motor">
            <hardwareInterface>hardware_interface/EffortJointInterface</hardwareInterface>
            <mechanicalReduction>1</mechanicalReduction>
        </actuator>
    </transmission>
    <transmission name="trans_s_mcp_pitch">
        <type>transmission_interface/SimpleTransmission</type>
        <joint name="s_mcp_pitch">
            <hardwareInterface>hardware_interface/EffortJointInterface</hardwareInterface>
        </joint>
        <actuator name="s_mcp_pitch_motor">
            <hardwareInterface>hardware_interface/EffortJointInterface</hardwareInterface>
            <mechanicalReduction>1</mechanicalReduction>
        </actuator>
    </transmission>
    <transmission name="trans_s_pip_pitch">
        <type>transmission_interface/SimpleTransmission</type>
        <joint name="s_pip_pitch">
            <hardwareInterface>hardware_interface/EffortJointInterface</hardwareInterface>
        </joint>
        <actuator name="s_pip_pitch_motor">
            <hardwareInterface>hardware_interface/EffortJointInterface</hardwareInterface>
            <mechanicalReduction>1</mechanicalReduction>
        </actuator>
    </transmission>
    <transmission name="trans_s_dip_pitch">
        <type>transmission_interface/SimpleTransmission</type>
        <joint name="s_dip_pitch">
            <hardwareInterface>hardware_interface/EffortJointInterface</hardwareInterface>
        </joint>
        <actuator name="s_dip_pitch_motor">
            <hardwareInterface>hardware_interface/EffortJointInterface</hardwareInterface>
            <mechanicalReduction>1</mechanicalReduction>
        </actuator>
    </transmission>
    <gazebo>
        <plugin name="gazebo_ros_control" filename="libgazebo_ros_control.so">
            <robotNamespace>/</robotNamespace>
        </plugin>
    </gazebo>
</robot>

<transmission name="t_mcp_pitch_tran">
        <type>transmission_interface/SimpleTransmission</type>
        <joint name="t_mcp_pitch">
            <hardwareInterface>hardware_interface/EffortJointInterface</hardwareInterface>
        </joint>
        <actuator name="t_mcp_pitch_actr">
            <hardwareInterface>hardware_interface/EffortJointInterface</hardwareInterface>
            <mechanicalReduction>1</mechanicalReduction>
        </actuator>
    </transmission>
    <transmission name="t_mcp_yaw_tran">
        <type>transmission_interface/SimpleTransmission</type>
        <joint name="t_mcp_yaw">
            <hardwareInterface>hardware_interface/EffortJointInterface</hardwareInterface>
        </joint>
        <actuator name="t_mcp_yaw_actr">
            <hardwareInterface>hardware_interface/EffortJointInterface</hardwareInterface>
            <mechanicalReduction>1</mechanicalReduction>
        </actuator>
    </transmission>
    <transmission name="t_pip_pitch_tran">
        <type>transmission_interface/SimpleTransmission</type>
        <joint name="t_pip_pitch">
            <hardwareInterface>hardware_interface/EffortJointInterface</hardwareInterface>
        </joint>
        <actuator name="t_pip_pitch_actr">
            <hardwareInterface>hardware_interface/EffortJointInterface</hardwareInterface>
            <mechanicalReduction>1</mechanicalReduction>
        </actuator>
    </transmission>
    <transmission name="i_mcp_yaw_tran">
        <type>transmission_interface/SimpleTransmission</type>
        <joint name="i_mcp_yaw">
            <hardwareInterface>hardware_interface/EffortJointInterface</hardwareInterface>
        </joint>
        <actuator name="i_mcp_yaw_actr">
            <hardwareInterface>hardware_interface/EffortJointInterface</hardwareInterface>
            <mechanicalReduction>1</mechanicalReduction>
        </actuator>
    </transmission>
    <transmission name="i_mcp_pitch_tran">
        <type>transmission_interface/SimpleTransmission</type>
        <joint name="i_mcp_pitch">
            <hardwareInterface>hardware_interface/EffortJointInterface</hardwareInterface>
        </joint>
        <actuator name="i_mcp_pitch_actr">
            <hardwareInterface>hardware_interface/EffortJointInterface</hardwareInterface>
            <mechanicalReduction>1</mechanicalReduction>
        </actuator>
    </transmission>
    <transmission name="i_pip_pitch_tran">
        <type>transmission_interface/SimpleTransmission</type>
        <joint name="i_pip_pitch">
            <hardwareInterface>hardware_interface/EffortJointInterface</hardwareInterface>
        </joint>
        <actuator name="i_pip_pitch_actr">
            <hardwareInterface>hardware_interface/EffortJointInterface</hardwareInterface>
            <mechanicalReduction>1</mechanicalReduction>
        </actuator>
    </transmission>
    <transmission name="i_dip_pitch_tran">
        <type>transmission_interface/SimpleTransmission</type>
        <joint name="i_dip_pitch">
            <hardwareInterface>hardware_interface/EffortJointInterface</hardwareInterface>
        </joint>
        <actuator name="i_dip_pitch_actr">
            <hardwareInterface>hardware_interface/EffortJointInterface</hardwareInterface>
            <mechanicalReduction>1</mechanicalReduction>
        </actuator>
    </transmission>
    <transmission name="m_mcp_yaw_tran">
        <type>transmission_interface/SimpleTransmission</type>
        <joint name="m_mcp_yaw">
            <hardwareInterface>hardware_interface/EffortJointInterface</hardwareInterface>
        </joint>
        <actuator name="m_mcp_yaw_actr">
            <hardwareInterface>hardware_interface/EffortJointInterface</hardwareInterface>
            <mechanicalReduction>1</mechanicalReduction>
        </actuator>
    </transmission>
    <transmission name="m_mcp_pitch_tran">
        <type>transmission_interface/SimpleTransmission</type>
        <joint name="m_mcp_pitch">
            <hardwareInterface>hardware_interface/EffortJointInterface</hardwareInterface>
        </joint>
        <actuator name="m_mcp_pitch_actr">
            <hardwareInterface>hardware_interface/EffortJointInterface</hardwareInterface>
            <mechanicalReduction>1</mechanicalReduction>
        </actuator>
    </transmission>
    <transmission name="m_pip_pitch_tran">
        <type>transmission_interface/SimpleTransmission</type>
        <joint name="m_pip_pitch">
            <hardwareInterface>hardware_interface/EffortJointInterface</hardwareInterface>
        </joint>
        <actuator name="m_pip_pitch_actr">
            <hardwareInterface>hardware_interface/EffortJointInterface</hardwareInterface>
            <mechanicalReduction>1</mechanicalReduction>
        </actuator>
    </transmission>
    <transmission name="m_dip_pitch_tran">
        <type>transmission_interface/SimpleTransmission</type>
        <joint name="m_dip_pitch">
            <hardwareInterface>hardware_interface/EffortJointInterface</hardwareInterface>
        </joint>
        <actuator name="m_dip_pitch_actr">
            <hardwareInterface>hardware_interface/EffortJointInterface</hardwareInterface>
            <mechanicalReduction>1</mechanicalReduction>
        </actuator>
    </transmission>
    <transmission name="r_mcp_yaw_tran">
        <type>transmission_interface/SimpleTransmission</type>
        <joint name="r_mcp_yaw">
            <hardwareInterface>hardware_interface/EffortJointInterface</hardwareInterface>
        </joint>
        <actuator name="r_mcp_yaw_actr">
            <hardwareInterface>hardware_interface/EffortJointInterface</hardwareInterface>
            <mechanicalReduction>1</mechanicalReduction>
        </actuator>
    </transmission>
    <transmission name="r_mcp_pitch_tran">
        <type>transmission_interface/SimpleTransmission</type>
        <joint name="r_mcp_pitch">
            <hardwareInterface>hardware_interface/EffortJointInterface</hardwareInterface>
        </joint>
        <actuator name="r_mcp_pitch_actr">
            <hardwareInterface>hardware_interface/EffortJointInterface</hardwareInterface>
            <mechanicalReduction>1</mechanicalReduction>
        </actuator>
    </transmission>
    <transmission name="r_pip_pitch_tran">
        <type>transmission_interface/SimpleTransmission</type>
        <joint name="r_pip_pitch">
            <hardwareInterface>hardware_interface/EffortJointInterface</hardwareInterface>
        </joint>
        <actuator name="r_pip_pitch_actr">
            <hardwareInterface>hardware_interface/EffortJointInterface</hardwareInterface>
            <mechanicalReduction>1</mechanicalReduction>
        </actuator>
    </transmission>
    <transmission name="r_dip_pitch_tran">
        <type>transmission_interface/SimpleTransmission</type>
        <joint name="r_dip_pitch">
            <hardwareInterface>hardware_interface/EffortJointInterface</hardwareInterface>
        </joint>
        <actuator name="r_dip_pitch_actr">
            <hardwareInterface>hardware_interface/EffortJointInterface</hardwareInterface>
            <mechanicalReduction>1</mechanicalReduction>
        </actuator>
    </transmission>
    <transmission name="s_mcp_yaw_tran">
        <type>transmission_interface/SimpleTransmission</type>
        <joint name="s_mcp_yaw">
            <hardwareInterface>hardware_interface/EffortJointInterface</hardwareInterface>
        </joint>
        <actuator name="s_mcp_yaw_actr">
            <hardwareInterface>hardware_interface/EffortJointInterface</hardwareInterface>
            <mechanicalReduction>1</mechanicalReduction>
        </actuator>
    </transmission>
    <transmission name="s_mcp_pitch_tran">
        <type>transmission_interface/SimpleTransmission</type>
        <joint name="s_mcp_pitch">
            <hardwareInterface>hardware_interface/EffortJointInterface</hardwareInterface>
        </joint>
        <actuator name="s_mcp_pitch_actr">
            <hardwareInterface>hardware_interface/EffortJointInterface</hardwareInterface>
            <mechanicalReduction>1</mechanicalReduction>
        </actuator>
    </transmission>
    <transmission name="s_pip_pitch_tran">
        <type>transmission_interface/SimpleTransmission</type>
        <joint name="s_pip_pitch">
            <hardwareInterface>hardware_interface/EffortJointInterface</hardwareInterface>
        </joint>
        <actuator name="s_pip_pitch_actr">
            <hardwareInterface>hardware_interface/EffortJointInterface</hardwareInterface>
            <mechanicalReduction>1</mechanicalReduction>
        </actuator>
    </transmission>
    <transmission name="s_dip_pitch_tran">
        <type>transmission_interface/SimpleTransmission</type>
        <joint name="s_dip_pitch">
            <hardwareInterface>hardware_interface/EffortJointInterface</hardwareInterface>
        </joint>
        <actuator name="s_dip_pitch_actr">
            <hardwareInterface>hardware_interface/EffortJointInterface</hardwareInterface>
            <mechanicalReduction>1</mechanicalReduction>
        </actuator>
    </transmission>
    <gazebo>
        <plugin filename="libgazebo_ros_control.so" name="control" />
    </gazebo>
    <gazebo reference="base_link">
        <material>Gazebo/Silver</material>
        <mu1>0.2</mu1>
        <mu2>0.2</mu2>
        <selfCollide>true</selfCollide>
        <gravity>true</gravity>
    </gazebo>
    <gazebo reference="cmc_link_v4_1">
        <material>Gazebo/Silver</material>
        <mu1>0.2</mu1>
        <mu2>0.2</mu2>
        <selfCollide>true</selfCollide>
    </gazebo>
    <gazebo reference="t_connector_1_v1_1">
        <material>Gazebo/Silver</material>
        <mu1>0.2</mu1>
        <mu2>0.2</mu2>
        <selfCollide>true</selfCollide>
    </gazebo>
    <gazebo reference="t_mcp_v5_1">
        <material>Gazebo/Silver</material>
        <mu1>0.2</mu1>
        <mu2>0.2</mu2>
        <selfCollide>true</selfCollide>
    </gazebo>
    <gazebo reference="t_pip_link_v5_1">
        <material>Gazebo/Silver</material>
        <mu1>0.2</mu1>
        <mu2>0.2</mu2>
        <selfCollide>true</selfCollide>
    </gazebo>
    <gazebo reference="t_connector_2_v1_1">
        <material>Gazebo/Silver</material>
        <mu1>0.2</mu1>
        <mu2>0.2</mu2>
        <selfCollide>true</selfCollide>
    </gazebo>
    <gazebo reference="t_tip_v2_1">
        <material>Gazebo/Silver</material>
        <mu1>0.2</mu1>
        <mu2>0.2</mu2>
        <selfCollide>true</selfCollide>
    </gazebo>
    <gazebo reference="i_mcp_yaw_link_v1_1">
        <material>Gazebo/Silver</material>
        <mu1>0.2</mu1>
        <mu2>0.2</mu2>
        <selfCollide>true</selfCollide>
    </gazebo>
    <gazebo reference="i_mcp_pitch_link_v1_1">
        <material>Gazebo/Silver</material>
        <mu1>0.2</mu1>
        <mu2>0.2</mu2>
        <selfCollide>true</selfCollide>
    </gazebo>
    <gazebo reference="i_connector_1_v1_1">
        <material>Gazebo/Silver</material>
        <mu1>0.2</mu1>
        <mu2>0.2</mu2>
        <selfCollide>true</selfCollide>
    </gazebo>
    <gazebo reference="i_pip_pitch_link_v4_1">
        <material>Gazebo/Silver</material>
        <mu1>0.2</mu1>
        <mu2>0.2</mu2>
        <selfCollide>true</selfCollide>
    </gazebo>
    <gazebo reference="i_connector_2_v1_1">
        <material>Gazebo/Silver</material>
        <mu1>0.2</mu1>
        <mu2>0.2</mu2>
        <selfCollide>true</selfCollide>
    </gazebo>
    <gazebo reference="i_dip_link_v2_1">
        <material>Gazebo/Silver</material>
        <mu1>0.2</mu1>
        <mu2>0.2</mu2>
        <selfCollide>true</selfCollide>
    </gazebo>
    <gazebo reference="i_connector_3_v1_1">
        <material>Gazebo/Silver</material>
        <mu1>0.2</mu1>
        <mu2>0.2</mu2>
        <selfCollide>true</selfCollide>
    </gazebo>
    <gazebo reference="i_tip_link_v2_1">
        <material>Gazebo/Silver</material>
        <mu1>0.2</mu1>
        <mu2>0.2</mu2>
        <selfCollide>true</selfCollide>
    </gazebo>
    <gazebo reference="m_mcp_yaw_link_v1_1">
        <material>Gazebo/Silver</material>
        <mu1>0.2</mu1>
        <mu2>0.2</mu2>
        <selfCollide>true</selfCollide>
    </gazebo>
    <gazebo reference="m_mcp_pitch_link_v1_1">
        <material>Gazebo/Silver</material>
        <mu1>0.2</mu1>
        <mu2>0.2</mu2>
        <selfCollide>true</selfCollide>
    </gazebo>
    <gazebo reference="m_connector_1_v1_1">
        <material>Gazebo/Silver</material>
        <mu1>0.2</mu1>
        <mu2>0.2</mu2>
        <selfCollide>true</selfCollide>
    </gazebo>
    <gazebo reference="m_pip_pitch_link_v2_1">
        <material>Gazebo/Silver</material>
        <mu1>0.2</mu1>
        <mu2>0.2</mu2>
        <selfCollide>true</selfCollide>
    </gazebo>
    <gazebo reference="m_connector_2_v1_1">
        <material>Gazebo/Silver</material>
        <mu1>0.2</mu1>
        <mu2>0.2</mu2>
        <selfCollide>true</selfCollide>
    </gazebo>
    <gazebo reference="m_dip_link_v2_1">
        <material>Gazebo/Silver</material>
        <mu1>0.2</mu1>
        <mu2>0.2</mu2>
        <selfCollide>true</selfCollide>
    </gazebo>
    <gazebo reference="m_connector_3_v1_1">
        <material>Gazebo/Silver</material>
        <mu1>0.2</mu1>
        <mu2>0.2</mu2>
        <selfCollide>true</selfCollide>
    </gazebo>
    <gazebo reference="m_tip_link_v2_1">
        <material>Gazebo/Silver</material>
        <mu1>0.2</mu1>
        <mu2>0.2</mu2>
        <selfCollide>true</selfCollide>
    </gazebo>
    <gazebo reference="r_mcp_yaw_link_v1_1">
        <material>Gazebo/Silver</material>
        <mu1>0.2</mu1>
        <mu2>0.2</mu2>
        <selfCollide>true</selfCollide>
    </gazebo>
    <gazebo reference="r_mcp_pitch_link_v1_1">
        <material>Gazebo/Silver</material>
        <mu1>0.2</mu1>
        <mu2>0.2</mu2>
        <selfCollide>true</selfCollide>
    </gazebo>
    <gazebo reference="r_connector_1_v1_1">
        <material>Gazebo/Silver</material>
        <mu1>0.2</mu1>
        <mu2>0.2</mu2>
        <selfCollide>true</selfCollide>
    </gazebo>
    <gazebo reference="r_pip_pitch_link_v2_1">
        <material>Gazebo/Silver</material>
        <mu1>0.2</mu1>
        <mu2>0.2</mu2>
        <selfCollide>true</selfCollide>
    </gazebo>
    <gazebo reference="r_connector_2_v1_1">
        <material>Gazebo/Silver</material>
        <mu1>0.2</mu1>
        <mu2>0.2</mu2>
        <selfCollide>true</selfCollide>
    </gazebo>
    <gazebo reference="r_dip_link_v2_1">
        <material>Gazebo/Silver</material>
        <mu1>0.2</mu1>
        <mu2>0.2</mu2>
        <selfCollide>true</selfCollide>
    </gazebo>
    <gazebo reference="r_connector_3_v1_1">
        <material>Gazebo/Silver</material>
        <mu1>0.2</mu1>
        <mu2>0.2</mu2>
        <selfCollide>true</selfCollide>
    </gazebo>
    <gazebo reference="r_tip_link_v2_1">
        <material>Gazebo/Silver</material>
        <mu1>0.2</mu1>
        <mu2>0.2</mu2>
        <selfCollide>true</selfCollide>
    </gazebo>
    <gazebo reference="s_mcp_yaw_link_v1_1">
        <material>Gazebo/Silver</material>
        <mu1>0.2</mu1>
        <mu2>0.2</mu2>
        <selfCollide>true</selfCollide>
    </gazebo>
    <gazebo reference="s_mcp_pitch_link_v1_1">
        <material>Gazebo/Silver</material>
        <mu1>0.2</mu1>
        <mu2>0.2</mu2>
        <selfCollide>true</selfCollide>
    </gazebo>
    <gazebo reference="s_connector_1_v1_1">
        <material>Gazebo/Silver</material>
        <mu1>0.2</mu1>
        <mu2>0.2</mu2>
        <selfCollide>true</selfCollide>
    </gazebo>
    <gazebo reference="s_pip_pitch_link_v2_1">
        <material>Gazebo/Silver</material>
        <mu1>0.2</mu1>
        <mu2>0.2</mu2>
        <selfCollide>true</selfCollide>
    </gazebo>
    <gazebo reference="s_connector_2_v1_1">
        <material>Gazebo/Silver</material>
        <mu1>0.2</mu1>
        <mu2>0.2</mu2>
        <selfCollide>true</selfCollide>
    </gazebo>
    <gazebo reference="s_dip_link_v2_1">
        <material>Gazebo/Silver</material>
        <mu1>0.2</mu1>
        <mu2>0.2</mu2>
        <selfCollide>true</selfCollide>
    </gazebo>
    <gazebo reference="s_connector_3_v1_1">
        <material>Gazebo/Silver</material>
        <mu1>0.2</mu1>
        <mu2>0.2</mu2>
        <selfCollide>true</selfCollide>
    </gazebo>
    <gazebo reference="s_tip_link_v2_1">
        <material>Gazebo/Silver</material>
        <mu1>0.2</mu1>
        <mu2>0.2</mu2>
        <selfCollide>true</selfCollide>
    </gazebo>
    <link name="base_link">
        <inertial>
            <origin rpy="0 0 0" xyz="-0.0018927237158815745 0.0009999999999999855 0.038608291526940605" />
            <mass value="0.1176699159976567" />
            <inertia ixx="6e-05" ixy="-0.0" ixz="7e-06" iyy="0.000149" iyz="0.0" izz="8.9e-05" />
        </inertial>
        <visual>
            <origin rpy="0 0 0" xyz="0 0 0" />
            <geometry>
                <mesh filename="package://hand_description/meshes/base_link.stl" scale="0.001 0.001 0.001" />
            </geometry>
            <material name="steel_satin" />
        </visual>
        <collision>
            <origin rpy="0 0 0" xyz="0 0 0" />
            <geometry>
                <mesh filename="package://hand_description/meshes/base_link.stl" scale="0.001 0.001 0.001" />
            </geometry>
        </collision>
    </link>
    <link name="cmc_link_v4_1">
        <inertial>
            <origin rpy="0 0 0" xyz="-0.00048645427795625945 -0.004769447524329848 -6.493517695722872e-06" />
            <mass value="0.018416700517789007" />
            <inertia ixx="5e-06" ixy="-0.0" ixz="0.0" iyy="5e-06" iyz="-0.0" izz="0.0" />
        </inertial>
        <visual>
            <origin rpy="0 0 0" xyz="-0.039 0.0 -0.0225" />
            <geometry>
                <mesh filename="package://hand_description/meshes/cmc_link_v4_1.stl" scale="0.001 0.001 0.001" />
            </geometry>
            <material name="steel_satin" />
        </visual>
        <collision>
            <origin rpy="0 0 0" xyz="-0.039 0.0 -0.0225" />
            <geometry>
                <mesh filename="package://hand_description/meshes/cmc_link_v4_1.stl" scale="0.001 0.001 0.001" />
            </geometry>
        </collision>
    </link>
    <link name="t_connector_1_v1_1">
        <inertial>
            <origin rpy="0 0 0" xyz="0.007499999970143861 -1.312864400526692e-11 -0.0012499999999999768" />
            <mass value="0.00374307805216622" />
            <inertia ixx="0.0" ixy="-0.0" ixz="-0.0" iyy="0.0" iyz="-0.0" izz="0.0" />
        </inertial>
        <visual>
            <origin rpy="0 0 0" xyz="-0.03825 0.007 -0.0225" />
            <geometry>
                <mesh filename="package://hand_description/meshes/t_connector_1_v1_1.stl" scale="0.001 0.001 0.001" />
            </geometry>
            <material name="steel_satin" />
        </visual>
        <collision>
            <origin rpy="0 0 0" xyz="-0.03825 0.007 -0.0225" />
            <geometry>
                <mesh filename="package://hand_description/meshes/t_connector_1_v1_1.stl" scale="0.001 0.001 0.001" />
            </geometry>
        </collision>
    </link>
    <link name="t_mcp_v5_1">
        <inertial>
            <origin rpy="0 0 0" xyz="0.007807400362975329 0.002936289856962501 -0.00016613310844226098" />
            <mass value="0.03943050014537037" />
            <inertia ixx="1.1e-05" ixy="-0.0" ixz="0.0" iyy="1.3e-05" iyz="-0.0" izz="3e-06" />
        </inertial>
        <visual>
            <origin rpy="0 0 0" xyz="-0.05325 0.007 -0.0225" />
            <geometry>
                <mesh filename="package://hand_description/meshes/t_mcp_v5_1.stl" scale="0.001 0.001 0.001" />
            </geometry>
            <material name="steel_satin" />
        </visual>
        <collision>
            <origin rpy="0 0 0" xyz="-0.05325 0.007 -0.0225" />
            <geometry>
                <mesh filename="package://hand_description/meshes/t_mcp_v5_1.stl" scale="0.001 0.001 0.001" />
            </geometry>
        </collision>
    </link>
    <link name="t_pip_link_v5_1">
        <inertial>
            <origin rpy="0 0 0" xyz="0.021556157971685322 -0.006243616814845158 2.555247680113837e-15" />
            <mass value="0.03216718051096679" />
            <inertia ixx="2e-06" ixy="1e-06" ixz="0.0" iyy="7e-06" iyz="-0.0" izz="6e-06" />
        </inertial>
        <visual>
            <origin rpy="0 0 0" xyz="-0.072947 0.004197 -0.014" />
            <geometry>
                <mesh filename="package://hand_description/meshes/t_pip_link_v5_1.stl" scale="0.001 0.001 0.001" />
            </geometry>
            <material name="steel_satin" />
        </visual>
        <collision>
            <origin rpy="0 0 0" xyz="-0.072947 0.004197 -0.014" />
            <geometry>
                <mesh filename="package://hand_description/meshes/t_pip_link_v5_1.stl" scale="0.001 0.001 0.001" />
            </geometry>
        </collision>
    </link>
    <link name="t_connector_2_v1_1">
        <inertial>
            <origin rpy="0 0 0" xyz="0.00749969926025644 3.0084577047270744e-07 -0.0002499999999999603" />
            <mass value="0.00374307805216622" />
            <inertia ixx="0.0" ixy="0.0" ixz="-0.0" iyy="0.0" iyz="-0.0" izz="0.0" />
        </inertial>
        <visual>
            <origin rpy="0 0 0" xyz="-0.108947 0.013197 -0.014" />
            <geometry>
                <mesh filename="package://hand_description/meshes/t_connector_2_v1_1.stl" scale="0.001 0.001 0.001" />
            </geometry>
            <material name="steel_satin" />
        </visual>
        <collision>
            <origin rpy="0 0 0" xyz="-0.108947 0.013197 -0.014" />
            <geometry>
                <mesh filename="package://hand_description/meshes/t_connector_2_v1_1.stl" scale="0.001 0.001 0.001" />
            </geometry>
        </collision>
    </link>
    <link name="t_tip_v2_1">
        <inertial>
            <origin rpy="0 0 0" xyz="0.001140939821871606 7.444969044555216e-08 0.0015000000000000378" />
            <mass value="0.011962131611831003" />
            <inertia ixx="1e-06" ixy="-0.0" ixz="0.0" iyy="1e-06" iyz="0.0" izz="0.0" />
        </inertial>
        <visual>
            <origin rpy="0 0 0" xyz="-0.123947 0.013197 -0.0125" />
            <geometry>
                <mesh filename="package://hand_description/meshes/t_tip_v2_1.stl" scale="0.001 0.001 0.001" />
            </geometry>
            <material name="steel_satin" />
        </visual>
        <collision>
            <origin rpy="0 0 0" xyz="-0.123947 0.013197 -0.0125" />
            <geometry>
                <mesh filename="package://hand_description/meshes/t_tip_v2_1.stl" scale="0.001 0.001 0.001" />
            </geometry>
        </collision>
    </link>
    <link name="i_mcp_yaw_link_v1_1">
        <inertial>
            <origin rpy="0 0 0" xyz="-3.172462292866385e-14 -0.0012359787607253364 0.0005366094686043744" />
            <mass value="0.011430485562037091" />
            <inertia ixx="2e-06" ixy="-0.0" ixz="0.0" iyy="3e-06" iyz="0.0" izz="0.0" />
        </inertial>
        <visual>
            <origin rpy="0 0 0" xyz="-0.0195 0.0 -0.0225" />
            <geometry>
                <mesh filename="package://hand_description/meshes/i_mcp_yaw_link_v1_1.stl" scale="0.001 0.001 0.001" />
            </geometry>
            <material name="steel_satin" />
        </visual>
        <collision>
            <origin rpy="0 0 0" xyz="-0.0195 0.0 -0.0225" />
            <geometry>
                <mesh filename="package://hand_description/meshes/i_mcp_yaw_link_v1_1.stl" scale="0.001 0.001 0.001" />
            </geometry>
        </collision>
    </link>
    <link name="i_mcp_pitch_link_v1_1">
        <inertial>
            <origin rpy="0 0 0" xyz="-4.586608870482678e-15 -0.005952105069446156 0.02420829596799528" />
            <mass value="0.026330610364773934" />
            <inertia ixx="5e-06" ixy="0.0" ixz="-0.0" iyy="6e-06" iyz="0.0" izz="2e-06" />
        </inertial>
        <visual>
            <origin rpy="0 0 0" xyz="-0.0195 0.002 -0.0405" />
            <geometry>
                <mesh filename="package://hand_description/meshes/i_mcp_pitch_link_v1_1.stl" scale="0.001 0.001 0.001" />
            </geometry>
            <material name="steel_satin" />
        </visual>
        <collision>
            <origin rpy="0 0 0" xyz="-0.0195 0.002 -0.0405" />
            <geometry>
                <mesh filename="package://hand_description/meshes/i_mcp_pitch_link_v1_1.stl" scale="0.001 0.001 0.001" />
            </geometry>
        </collision>
    </link>
    <link name="i_connector_1_v1_1">
        <inertial>
            <origin rpy="0 0 0" xyz="0.0002500000000000002 -3.469446951953614e-17 0.007499999970251525" />
            <mass value="0.00374307805216622" />
            <inertia ixx="0.0" ixy="0.0" ixz="0.0" iyy="0.0" iyz="0.0" izz="0.0" />
        </inertial>
        <visual>
            <origin rpy="0 0 0" xyz="-0.0195 0.00925 -0.0815" />
            <geometry>
                <mesh filename="package://hand_description/meshes/i_connector_1_v1_1.stl" scale="0.001 0.001 0.001" />
            </geometry>
            <material name="steel_satin" />
        </visual>
        <collision>
            <origin rpy="0 0 0" xyz="-0.0195 0.00925 -0.0815" />
            <geometry>
                <mesh filename="package://hand_description/meshes/i_connector_1_v1_1.stl" scale="0.001 0.001 0.001" />
            </geometry>
        </collision>
    </link>
    <link name="i_pip_pitch_link_v4_1">
        <inertial>
            <origin rpy="0 0 0" xyz="0.0010000000000000044 0.001096507521878223 0.018000000026317478" />
            <mass value="0.0314105238001653" />
            <inertia ixx="7e-06" ixy="-0.0" ixz="0.0" iyy="8e-06" iyz="-0.0" izz="2e-06" />
        </inertial>
        <visual>
            <origin rpy="0 0 0" xyz="-0.0185 0.00925 -0.0965" />
            <geometry>
                <mesh filename="package://hand_description/meshes/i_pip_pitch_link_v4_1.stl" scale="0.001 0.001 0.001" />
            </geometry>
            <material name="steel_satin" />
        </visual>
        <collision>
            <origin rpy="0 0 0" xyz="-0.0185 0.00925 -0.0965" />
            <geometry>
                <mesh filename="package://hand_description/meshes/i_pip_pitch_link_v4_1.stl" scale="0.001 0.001 0.001" />
            </geometry>
        </collision>
    </link>
    <link name="i_connector_2_v1_1">
        <inertial>
            <origin rpy="0 0 0" xyz="0.0002500000000000002 -5.0306980803327406e-17 0.007499999970251553" />
            <mass value="0.00374307805216622" />
            <inertia ixx="0.0" ixy="-0.0" ixz="0.0" iyy="0.0" iyz="0.0" izz="0.0" />
        </inertial>
        <visual>
            <origin rpy="0 0 0" xyz="-0.0195 0.00925 -0.1325" />
            <geometry>
                <mesh filename="package://hand_description/meshes/i_connector_2_v1_1.stl" scale="0.001 0.001 0.001" />
            </geometry>
            <material name="steel_satin" />
        </visual>
        <collision>
            <origin rpy="0 0 0" xyz="-0.0195 0.00925 -0.1325" />
            <geometry>
                <mesh filename="package://hand_description/meshes/i_connector_2_v1_1.stl" scale="0.001 0.001 0.001" />
            </geometry>
        </collision>
    </link>
    <link name="i_dip_link_v2_1">
        <inertial>
            <origin rpy="0 0 0" xyz="0.0010000228538777876 0.000633326000430515 0.005499983676315989" />
            <mass value="0.0165936992661325" />
            <inertia ixx="1e-06" ixy="0.0" ixz="0.0" iyy="1e-06" iyz="-0.0" izz="1e-06" />
        </inertial>
        <visual>
            <origin rpy="0 0 0" xyz="-0.0185 0.00925 -0.1475" />
            <geometry>
                <mesh filename="package://hand_description/meshes/i_dip_link_v2_1.stl" scale="0.001 0.001 0.001" />
            </geometry>
            <material name="steel_satin" />
        </visual>
        <collision>
            <origin rpy="0 0 0" xyz="-0.0185 0.00925 -0.1475" />
            <geometry>
                <mesh filename="package://hand_description/meshes/i_dip_link_v2_1.stl" scale="0.001 0.001 0.001" />
            </geometry>
        </collision>
    </link>
    <link name="i_connector_3_v1_1">
        <inertial>
            <origin rpy="0 0 0" xyz="0.00025000000000001063 -7.632783294297951e-17 0.007499999970251553" />
            <mass value="0.00374307805216622" />
            <inertia ixx="0.0" ixy="-0.0" ixz="0.0" iyy="0.0" iyz="0.0" izz="0.0" />
        </inertial>
        <visual>
            <origin rpy="0 0 0" xyz="-0.0195 0.00925 -0.1585" />
            <geometry>
                <mesh filename="package://hand_description/meshes/i_connector_3_v1_1.stl" scale="0.001 0.001 0.001" />
            </geometry>
            <material name="steel_satin" />
        </visual>
        <collision>
            <origin rpy="0 0 0" xyz="-0.0195 0.00925 -0.1585" />
            <geometry>
                <mesh filename="package://hand_description/meshes/i_connector_3_v1_1.stl" scale="0.001 0.001 0.001" />
            </geometry>
        </collision>
    </link>
    <link name="i_tip_link_v2_1">
        <inertial>
            <origin rpy="0 0 0" xyz="-0.0014999771461222076 0.0006333260004305029 0.005499983676315989" />
            <mass value="0.0165936992661325" />
            <inertia ixx="1e-06" ixy="0.0" ixz="0.0" iyy="1e-06" iyz="-0.0" izz="1e-06" />
        </inertial>
        <visual>
            <origin rpy="0 0 0" xyz="-0.021 0.00925 -0.1735" />
            <geometry>
                <mesh filename="package://hand_description/meshes/i_tip_link_v2_1.stl" scale="0.001 0.001 0.001" />
            </geometry>
            <material name="steel_satin" />
        </visual>
        <collision>
            <origin rpy="0 0 0" xyz="-0.021 0.00925 -0.1735" />
            <geometry>
                <mesh filename="package://hand_description/meshes/i_tip_link_v2_1.stl" scale="0.001 0.001 0.001" />
            </geometry>
        </collision>
    </link>
    <link name="m_mcp_yaw_link_v1_1">
        <inertial>
            <origin rpy="0 0 0" xyz="1.7623359342441685e-14 -0.0012359787607253386 0.0005366094686043675" />
            <mass value="0.011430485562037091" />
            <inertia ixx="2e-06" ixy="0.0" ixz="-0.0" iyy="3e-06" iyz="0.0" izz="0.0" />
        </inertial>
        <visual>
            <origin rpy="0 0 0" xyz="-0.0 0.0 -0.0225" />
            <geometry>
                <mesh filename="package://hand_description/meshes/m_mcp_yaw_link_v1_1.stl" scale="0.001 0.001 0.001" />
            </geometry>
            <material name="steel_satin" />
        </visual>
        <collision>
            <origin rpy="0 0 0" xyz="-0.0 0.0 -0.0225" />
            <geometry>
                <mesh filename="package://hand_description/meshes/m_mcp_yaw_link_v1_1.stl" scale="0.001 0.001 0.001" />
            </geometry>
        </collision>
    </link>
    <link name="m_mcp_pitch_link_v1_1">
        <inertial>
            <origin rpy="0 0 0" xyz="-4.5964789723509935e-15 -0.005952105069446156 0.024208295967995265" />
            <mass value="0.026330610364773934" />
            <inertia ixx="5e-06" ixy="0.0" ixz="-0.0" iyy="6e-06" iyz="0.0" izz="2e-06" />
        </inertial>
        <visual>
            <origin rpy="0 0 0" xyz="0.0 0.002 -0.0405" />
            <geometry>
                <mesh filename="package://hand_description/meshes/m_mcp_pitch_link_v1_1.stl" scale="0.001 0.001 0.001" />
            </geometry>
            <material name="steel_satin" />
        </visual>
        <collision>
            <origin rpy="0 0 0" xyz="0.0 0.002 -0.0405" />
            <geometry>
                <mesh filename="package://hand_description/meshes/m_mcp_pitch_link_v1_1.stl" scale="0.001 0.001 0.001" />
            </geometry>
        </collision>
    </link>
    <link name="m_connector_1_v1_1">
        <inertial>
            <origin rpy="0 0 0" xyz="0.00024999999999998857 -1.0581813203458523e-16 0.007499999970251525" />
            <mass value="0.00374307805216622" />
            <inertia ixx="0.0" ixy="-0.0" ixz="-0.0" iyy="0.0" iyz="0.0" izz="0.0" />
        </inertial>
        <visual>
            <origin rpy="0 0 0" xyz="0.0 0.00925 -0.0815" />
            <geometry>
                <mesh filename="package://hand_description/meshes/m_connector_1_v1_1.stl" scale="0.001 0.001 0.001" />
            </geometry>
            <material name="steel_satin" />
        </visual>
        <collision>
            <origin rpy="0 0 0" xyz="0.0 0.00925 -0.0815" />
            <geometry>
                <mesh filename="package://hand_description/meshes/m_connector_1_v1_1.stl" scale="0.001 0.001 0.001" />
            </geometry>
        </collision>
    </link>
    <link name="m_pip_pitch_link_v2_1">
        <inertial>
            <origin rpy="0 0 0" xyz="-0.0015000000000000044 0.0009393881307711328 0.018008883353284405" />
            <mass value="0.0314105238001653" />
            <inertia ixx="7e-06" ixy="-0.0" ixz="0.0" iyy="8e-06" iyz="0.0" izz="2e-06" />
        </inertial>
        <visual>
            <origin rpy="0 0 0" xyz="-0.0015 0.00925 -0.0965" />
            <geometry>
                <mesh filename="package://hand_description/meshes/m_pip_pitch_link_v2_1.stl" scale="0.001 0.001 0.001" />
            </geometry>
            <material name="steel_satin" />
        </visual>
        <collision>
            <origin rpy="0 0 0" xyz="-0.0015 0.00925 -0.0965" />
            <geometry>
                <mesh filename="package://hand_description/meshes/m_pip_pitch_link_v2_1.stl" scale="0.001 0.001 0.001" />
            </geometry>
        </collision>
    </link>
    <link name="m_connector_2_v1_1">
        <inertial>
            <origin rpy="0 0 0" xyz="0.00025000000000000857 -6.560429417987179e-05 0.007499343623543014" />
            <mass value="0.00374307805216622" />
            <inertia ixx="0.0" ixy="-0.0" ixz="0.0" iyy="0.0" iyz="0.0" izz="0.0" />
        </inertial>
        <visual>
            <origin rpy="0 0 0" xyz="-0.0 0.009564 -0.132499" />
            <geometry>
                <mesh filename="package://hand_description/meshes/m_connector_2_v1_1.stl" scale="0.001 0.001 0.001" />
            </geometry>
            <material name="steel_satin" />
        </visual>
        <collision>
            <origin rpy="0 0 0" xyz="-0.0 0.009564 -0.132499" />
            <geometry>
                <mesh filename="package://hand_description/meshes/m_connector_2_v1_1.stl" scale="0.001 0.001 0.001" />
            </geometry>
        </collision>
    </link>
    <link name="m_dip_link_v2_1">
        <inertial>
            <origin rpy="0 0 0" xyz="-0.0014999771461222094 0.0005852527718479845 0.005505359071886956" />
            <mass value="0.0165936992661325" />
            <inertia ixx="1e-06" ixy="0.0" ixz="0.0" iyy="1e-06" iyz="0.0" izz="1e-06" />
        </inertial>
        <visual>
            <origin rpy="0 0 0" xyz="-0.0015 0.009695 -0.147498" />
            <geometry>
                <mesh filename="package://hand_description/meshes/m_dip_link_v2_1.stl" scale="0.001 0.001 0.001" />
            </geometry>
            <material name="steel_satin" />
        </visual>
        <collision>
            <origin rpy="0 0 0" xyz="-0.0015 0.009695 -0.147498" />
            <geometry>
                <mesh filename="package://hand_description/meshes/m_dip_link_v2_1.stl" scale="0.001 0.001 0.001" />
            </geometry>
        </collision>
    </link>
    <link name="m_connector_3_v1_1">
        <inertial>
            <origin rpy="0 0 0" xyz="0.0002499999999999933 -6.549421713753119e-05 0.00749935362321158" />
            <mass value="0.00374307805216622" />
            <inertia ixx="0.0" ixy="0.0" ixz="-0.0" iyy="0.0" iyz="0.0" izz="0.0" />
        </inertial>
        <visual>
            <origin rpy="0 0 0" xyz="-0.0 0.009791 -0.158498" />
            <geometry>
                <mesh filename="package://hand_description/meshes/m_connector_3_v1_1.stl" scale="0.001 0.001 0.001" />
            </geometry>
            <material name="steel_satin" />
        </visual>
        <collision>
            <origin rpy="0 0 0" xyz="-0.0 0.009791 -0.158498" />
            <geometry>
                <mesh filename="package://hand_description/meshes/m_connector_3_v1_1.stl" scale="0.001 0.001 0.001" />
            </geometry>
        </collision>
    </link>
    <link name="m_tip_link_v2_1">
        <inertial>
            <origin rpy="0 0 0" xyz="-0.0014999771461222285 0.0005853628488903233 0.005505369071555438" />
            <mass value="0.0165936992661325" />
            <inertia ixx="1e-06" ixy="0.0" ixz="0.0" iyy="1e-06" iyz="0.0" izz="1e-06" />
        </inertial>
        <visual>
            <origin rpy="0 0 0" xyz="-0.0015 0.009922 -0.173497" />
            <geometry>
                <mesh filename="package://hand_description/meshes/m_tip_link_v2_1.stl" scale="0.001 0.001 0.001" />
            </geometry>
            <material name="steel_satin" />
        </visual>
        <collision>
            <origin rpy="0 0 0" xyz="-0.0015 0.009922 -0.173497" />
            <geometry>
                <mesh filename="package://hand_description/meshes/m_tip_link_v2_1.stl" scale="0.001 0.001 0.001" />
            </geometry>
        </collision>
    </link>
    <link name="r_mcp_yaw_link_v1_1">
        <inertial>
            <origin rpy="0 0 0" xyz="-3.17280923756158e-14 -0.0012359787607253358 0.0005366094686043987" />
            <mass value="0.011430485562037091" />
            <inertia ixx="2e-06" ixy="-0.0" ixz="0.0" iyy="3e-06" iyz="0.0" izz="0.0" />
        </inertial>
        <visual>
            <origin rpy="0 0 0" xyz="0.0195 0.0 -0.0225" />
            <geometry>
                <mesh filename="package://hand_description/meshes/r_mcp_yaw_link_v1_1.stl" scale="0.001 0.001 0.001" />
            </geometry>
            <material name="steel_satin" />
        </visual>
        <collision>
            <origin rpy="0 0 0" xyz="0.0195 0.0 -0.0225" />
            <geometry>
                <mesh filename="package://hand_description/meshes/r_mcp_yaw_link_v1_1.stl" scale="0.001 0.001 0.001" />
            </geometry>
        </collision>
    </link>
    <link name="r_mcp_pitch_link_v1_1">
        <inertial>
            <origin rpy="0 0 0" xyz="-4.593547764386585e-15 -0.005952105069446156 0.024208295967995307" />
            <mass value="0.026330610364773934" />
            <inertia ixx="5e-06" ixy="0.0" ixz="-0.0" iyy="6e-06" iyz="0.0" izz="2e-06" />
        </inertial>
        <visual>
            <origin rpy="0 0 0" xyz="0.0195 0.002 -0.0405" />
            <geometry>
                <mesh filename="package://hand_description/meshes/r_mcp_pitch_link_v1_1.stl" scale="0.001 0.001 0.001" />
            </geometry>
            <material name="steel_satin" />
        </visual>
        <collision>
            <origin rpy="0 0 0" xyz="0.0195 0.002 -0.0405" />
            <geometry>
                <mesh filename="package://hand_description/meshes/r_mcp_pitch_link_v1_1.stl" scale="0.001 0.001 0.001" />
            </geometry>
        </collision>
    </link>
    <link name="r_connector_1_v1_1">
        <inertial>
            <origin rpy="0 0 0" xyz="0.00024999999999999675 -2.6020852139652106e-17 0.007499999970251553" />
            <mass value="0.00374307805216622" />
            <inertia ixx="0.0" ixy="-0.0" ixz="-0.0" iyy="0.0" iyz="0.0" izz="0.0" />
        </inertial>
        <visual>
            <origin rpy="0 0 0" xyz="0.0195 0.00925 -0.0815" />
            <geometry>
                <mesh filename="package://hand_description/meshes/r_connector_1_v1_1.stl" scale="0.001 0.001 0.001" />
            </geometry>
            <material name="steel_satin" />
        </visual>
        <collision>
            <origin rpy="0 0 0" xyz="0.0195 0.00925 -0.0815" />
            <geometry>
                <mesh filename="package://hand_description/meshes/r_connector_1_v1_1.stl" scale="0.001 0.001 0.001" />
            </geometry>
        </collision>
    </link>
    <link name="r_pip_pitch_link_v2_1">
        <inertial>
            <origin rpy="0 0 0" xyz="-0.001500000000000029 0.00109650752187823 0.017999999914078108" />
            <mass value="0.0314105238001653" />
            <inertia ixx="7e-06" ixy="0.0" ixz="-0.0" iyy="8e-06" iyz="0.0" izz="2e-06" />
        </inertial>
        <visual>
            <origin rpy="0 0 0" xyz="0.018 0.00925 -0.0965" />
            <geometry>
                <mesh filename="package://hand_description/meshes/r_pip_pitch_link_v2_1.stl" scale="0.001 0.001 0.001" />
            </geometry>
            <material name="steel_satin" />
        </visual>
        <collision>
            <origin rpy="0 0 0" xyz="0.018 0.00925 -0.0965" />
            <geometry>
                <mesh filename="package://hand_description/meshes/r_pip_pitch_link_v2_1.stl" scale="0.001 0.001 0.001" />
            </geometry>
        </collision>
    </link>
    <link name="r_connector_2_v1_1">
        <inertial>
            <origin rpy="0 0 0" xyz="0.0002499999999999343 -3.122502256758253e-17 0.0074999999702514974" />
            <mass value="0.00374307805216622" />
            <inertia ixx="0.0" ixy="-0.0" ixz="0.0" iyy="0.0" iyz="0.0" izz="0.0" />
        </inertial>
        <visual>
            <origin rpy="0 0 0" xyz="0.0195 0.00925 -0.1325" />
            <geometry>
                <mesh filename="package://hand_description/meshes/r_connector_2_v1_1.stl" scale="0.001 0.001 0.001" />
            </geometry>
            <material name="steel_satin" />
        </visual>
        <collision>
            <origin rpy="0 0 0" xyz="0.0195 0.00925 -0.1325" />
            <geometry>
                <mesh filename="package://hand_description/meshes/r_connector_2_v1_1.stl" scale="0.001 0.001 0.001" />
            </geometry>
        </collision>
    </link>
    <link name="r_dip_link_v2_1">
        <inertial>
            <origin rpy="0 0 0" xyz="0.0010000228538776974 0.0006333260004305185 0.005499983676316045" />
            <mass value="0.0165936992661325" />
            <inertia ixx="1e-06" ixy="0.0" ixz="0.0" iyy="1e-06" iyz="-0.0" izz="1e-06" />
        </inertial>
        <visual>
            <origin rpy="0 0 0" xyz="0.0205 0.00925 -0.1475" />
            <geometry>
                <mesh filename="package://hand_description/meshes/r_dip_link_v2_1.stl" scale="0.001 0.001 0.001" />
            </geometry>
            <material name="steel_satin" />
        </visual>
        <collision>
            <origin rpy="0 0 0" xyz="0.0205 0.00925 -0.1475" />
            <geometry>
                <mesh filename="package://hand_description/meshes/r_dip_link_v2_1.stl" scale="0.001 0.001 0.001" />
            </geometry>
        </collision>
    </link>
    <link name="r_connector_3_v1_1">
        <inertial>
            <origin rpy="0 0 0" xyz="0.00024999999999991 3.122502256758253e-17 0.0074999999702516085" />
            <mass value="0.00374307805216622" />
            <inertia ixx="0.0" ixy="0.0" ixz="0.0" iyy="0.0" iyz="0.0" izz="0.0" />
        </inertial>
        <visual>
            <origin rpy="0 0 0" xyz="0.0195 0.00925 -0.1585" />
            <geometry>
                <mesh filename="package://hand_description/meshes/r_connector_3_v1_1.stl" scale="0.001 0.001 0.001" />
            </geometry>
            <material name="steel_satin" />
        </visual>
        <collision>
            <origin rpy="0 0 0" xyz="0.0195 0.00925 -0.1585" />
            <geometry>
                <mesh filename="package://hand_description/meshes/r_connector_3_v1_1.stl" scale="0.001 0.001 0.001" />
            </geometry>
        </collision>
    </link>
    <link name="r_tip_link_v2_1">
        <inertial>
            <origin rpy="0 0 0" xyz="0.0010000228538776766 0.000633326000430548 0.005499983676316017" />
            <mass value="0.0165936992661325" />
            <inertia ixx="1e-06" ixy="0.0" ixz="0.0" iyy="1e-06" iyz="-0.0" izz="1e-06" />
        </inertial>
        <visual>
            <origin rpy="0 0 0" xyz="0.0205 0.00925 -0.1735" />
            <geometry>
                <mesh filename="package://hand_description/meshes/r_tip_link_v2_1.stl" scale="0.001 0.001 0.001" />
            </geometry>
            <material name="steel_satin" />
        </visual>
        <collision>
            <origin rpy="0 0 0" xyz="0.0205 0.00925 -0.1735" />
            <geometry>
                <mesh filename="package://hand_description/meshes/r_tip_link_v2_1.stl" scale="0.001 0.001 0.001" />
            </geometry>
        </collision>
    </link>
    <link name="s_mcp_yaw_link_v1_1">
        <inertial>
            <origin rpy="0 0 0" xyz="-3.1731561822567755e-14 -0.0012359787607253373 0.0005366094686043744" />
            <mass value="0.011430485562037091" />
            <inertia ixx="2e-06" ixy="-0.0" ixz="0.0" iyy="3e-06" iyz="0.0" izz="0.0" />
        </inertial>
        <visual>
            <origin rpy="0 0 0" xyz="0.039 0.0 -0.0225" />
            <geometry>
                <mesh filename="package://hand_description/meshes/s_mcp_yaw_link_v1_1.stl" scale="0.001 0.001 0.001" />
            </geometry>
            <material name="steel_satin" />
        </visual>
        <collision>
            <origin rpy="0 0 0" xyz="0.039 0.0 -0.0225" />
            <geometry>
                <mesh filename="package://hand_description/meshes/s_mcp_yaw_link_v1_1.stl" scale="0.001 0.001 0.001" />
            </geometry>
        </collision>
    </link>
    <link name="s_mcp_pitch_link_v1_1">
        <inertial>
            <origin rpy="0 0 0" xyz="-4.5727310826748635e-15 -0.005952105069446158 0.024208295967995265" />
            <mass value="0.026330610364773934" />
            <inertia ixx="5e-06" ixy="0.0" ixz="-0.0" iyy="6e-06" iyz="0.0" izz="2e-06" />
        </inertial>
        <visual>
            <origin rpy="0 0 0" xyz="0.039 0.002 -0.0405" />
            <geometry>
                <mesh filename="package://hand_description/meshes/s_mcp_pitch_link_v1_1.stl" scale="0.001 0.001 0.001" />
            </geometry>
            <material name="steel_satin" />
        </visual>
        <collision>
            <origin rpy="0 0 0" xyz="0.039 0.002 -0.0405" />
            <geometry>
                <mesh filename="package://hand_description/meshes/s_mcp_pitch_link_v1_1.stl" scale="0.001 0.001 0.001" />
            </geometry>
        </collision>
    </link>
    <link name="s_connector_1_v1_1">
        <inertial>
            <origin rpy="0 0 0" xyz="0.0002500000000000141 -3.9898639947466563e-17 0.007499999970143861" />
            <mass value="0.00374307805216622" />
            <inertia ixx="0.0" ixy="0.0" ixz="0.0" iyy="0.0" iyz="-0.0" izz="0.0" />
        </inertial>
        <visual>
            <origin rpy="0 0 0" xyz="0.039 0.00925 -0.0815" />
            <geometry>
                <mesh filename="package://hand_description/meshes/s_connector_1_v1_1.stl" scale="0.001 0.001 0.001" />
            </geometry>
            <material name="steel_satin" />
        </visual>
        <collision>
            <origin rpy="0 0 0" xyz="0.039 0.00925 -0.0815" />
            <geometry>
                <mesh filename="package://hand_description/meshes/s_connector_1_v1_1.stl" scale="0.001 0.001 0.001" />
            </geometry>
        </collision>
    </link>
    <link name="s_pip_pitch_link_v2_1">
        <inertial>
            <origin rpy="0 0 0" xyz="0.0010000000000000009 0.0010965075218782126 0.018000000026317423" />
            <mass value="0.0314105238001653" />
            <inertia ixx="7e-06" ixy="0.0" ixz="-0.0" iyy="8e-06" iyz="-0.0" izz="2e-06" />
        </inertial>
        <visual>
            <origin rpy="0 0 0" xyz="0.04 0.00925 -0.0965" />
            <geometry>
                <mesh filename="package://hand_description/meshes/s_pip_pitch_link_v2_1.stl" scale="0.001 0.001 0.001" />
            </geometry>
            <material name="steel_satin" />
        </visual>
        <collision>
            <origin rpy="0 0 0" xyz="0.04 0.00925 -0.0965" />
            <geometry>
                <mesh filename="package://hand_description/meshes/s_pip_pitch_link_v2_1.stl" scale="0.001 0.001 0.001" />
            </geometry>
        </collision>
    </link>
    <link name="s_connector_2_v1_1">
        <inertial>
            <origin rpy="0 0 0" xyz="0.00025000000000002104 -1.0408340855860843e-17 0.007499999970143834" />
            <mass value="0.00374307805216622" />
            <inertia ixx="0.0" ixy="0.0" ixz="0.0" iyy="0.0" iyz="-0.0" izz="0.0" />
        </inertial>
        <visual>
            <origin rpy="0 0 0" xyz="0.039 0.00925 -0.1325" />
            <geometry>
                <mesh filename="package://hand_description/meshes/s_connector_2_v1_1.stl" scale="0.001 0.001 0.001" />
            </geometry>
            <material name="steel_satin" />
        </visual>
        <collision>
            <origin rpy="0 0 0" xyz="0.039 0.00925 -0.1325" />
            <geometry>
                <mesh filename="package://hand_description/meshes/s_connector_2_v1_1.stl" scale="0.001 0.001 0.001" />
            </geometry>
        </collision>
    </link>
    <link name="s_dip_link_v2_1">
        <inertial>
            <origin rpy="0 0 0" xyz="0.0010000228538777495 0.0006333260004305966 0.0054999836763159615" />
            <mass value="0.0165936992661325" />
            <inertia ixx="1e-06" ixy="0.0" ixz="0.0" iyy="1e-06" iyz="-0.0" izz="1e-06" />
        </inertial>
        <visual>
            <origin rpy="0 0 0" xyz="0.04 0.00925 -0.1475" />
            <geometry>
                <mesh filename="package://hand_description/meshes/s_dip_link_v2_1.stl" scale="0.001 0.001 0.001" />
            </geometry>
            <material name="steel_satin" />
        </visual>
        <collision>
            <origin rpy="0 0 0" xyz="0.04 0.00925 -0.1475" />
            <geometry>
                <mesh filename="package://hand_description/meshes/s_dip_link_v2_1.stl" scale="0.001 0.001 0.001" />
            </geometry>
        </collision>
    </link>
    <link name="s_connector_3_v1_1">
        <inertial>
            <origin rpy="0 0 0" xyz="0.00025000000000005573 -5.898059818321144e-17 0.007499999970251581" />
            <mass value="0.00374307805216622" />
            <inertia ixx="0.0" ixy="-0.0" ixz="0.0" iyy="0.0" iyz="0.0" izz="0.0" />
        </inertial>
        <visual>
            <origin rpy="0 0 0" xyz="0.039 0.00925 -0.1585" />
            <geometry>
                <mesh filename="package://hand_description/meshes/s_connector_3_v1_1.stl" scale="0.001 0.001 0.001" />
            </geometry>
            <material name="steel_satin" />
        </visual>
        <collision>
            <origin rpy="0 0 0" xyz="0.039 0.00925 -0.1585" />
            <geometry>
                <mesh filename="package://hand_description/meshes/s_connector_3_v1_1.stl" scale="0.001 0.001 0.001" />
            </geometry>
        </collision>
    </link>
    <link name="s_tip_link_v2_1">
        <inertial>
            <origin rpy="0 0 0" xyz="0.0010000228538778189 0.0006333260004305445 0.005499983676316045" />
            <mass value="0.0165936992661325" />
            <inertia ixx="1e-06" ixy="0.0" ixz="0.0" iyy="1e-06" iyz="-0.0" izz="1e-06" />
        </inertial>
        <visual>
            <origin rpy="0 0 0" xyz="0.04 0.00925 -0.1735" />
            <geometry>
                <mesh filename="package://hand_description/meshes/s_tip_link_v2_1.stl" scale="0.001 0.001 0.001" />
            </geometry>
            <material name="steel_satin" />
        </visual>
        <collision>
            <origin rpy="0 0 0" xyz="0.04 0.00925 -0.1735" />
            <geometry>
                <mesh filename="package://hand_description/meshes/s_tip_link_v2_1.stl" scale="0.001 0.001 0.001" />
            </geometry>
        </collision>
    </link>
    <joint name="Rigid1" type="fixed">
        <origin rpy="0 0 0" xyz="0.039 0.0 0.0225" />
        <parent link="base_link" />
        <child link="cmc_link_v4_1" />
    </joint>
    <joint name="t_mcp_pitch" type="continuous">
        <origin rpy="0 0 0" xyz="-0.00075 -0.007 0.0" />
        <parent link="cmc_link_v4_1" />
        <child link="t_connector_1_v1_1" />
        <axis xyz="0.0 0.0 -1.0" />
    </joint>
    <joint name="Rigid3" type="fixed">
        <origin rpy="0 0 0" xyz="0.015 0.0 0.0" />
        <parent link="t_connector_1_v1_1" />
        <child link="t_mcp_v5_1" />
    </joint>
    <joint name="t_mcp_yaw" type="continuous">
        <origin rpy="0 0 0" xyz="0.019697 0.002803 -0.0085" />
        <parent link="t_mcp_v5_1" />
        <child link="t_pip_link_v5_1" />
        <axis xyz="0.0 -1.0 -0.0" />
    </joint>
    <joint name="t_pip_pitch" type="continuous">
        <origin rpy="0 0 0" xyz="0.036 -0.009 0.0" />
        <parent link="t_pip_link_v5_1" />
        <child link="t_connector_2_v1_1" />
        <axis xyz="-0.0 0.0 -1.0" />
    </joint>
    <joint name="Rigid6" type="fixed">
        <origin rpy="0 0 0" xyz="0.015 0.0 -0.0015" />
        <parent link="t_connector_2_v1_1" />
        <child link="t_tip_v2_1" />
    </joint>
    <joint name="Rigid7" type="fixed">
        <origin rpy="0 0 0" xyz="0.0195 0.0 0.0225" />
        <parent link="base_link" />
        <child link="i_mcp_yaw_link_v1_1" />
    </joint>
    <joint name="i_mcp_yaw" type="continuous">
        <origin rpy="0 0 0" xyz="0.0 -0.002 0.018" />
        <parent link="i_mcp_yaw_link_v1_1" />
        <child link="i_mcp_pitch_link_v1_1" />
        <axis xyz="0.0 -1.0 -0.0" />
    </joint>
    <joint name="i_mcp_pitch" type="continuous">
        <origin rpy="0 0 0" xyz="0.0 -0.00725 0.041" />
        <parent link="i_mcp_pitch_link_v1_1" />
        <child link="i_connector_1_v1_1" />
        <axis xyz="-1.0 0.0 0.0" />
    </joint>
    <joint name="Rigid11" type="fixed">
        <origin rpy="0 0 0" xyz="-0.001 0.0 0.015" />
        <parent link="i_connector_1_v1_1" />
        <child link="i_pip_pitch_link_v4_1" />
    </joint>
    <joint name="i_pip_pitch" type="continuous">
        <origin rpy="0 0 0" xyz="0.001 0.0 0.036" />
        <parent link="i_pip_pitch_link_v4_1" />
        <child link="i_connector_2_v1_1" />
        <axis xyz="-1.0 0.0 0.0" />
    </joint>
    <joint name="Rigid16" type="fixed">
        <origin rpy="0 0 0" xyz="-0.001 0.0 0.015" />
        <parent link="i_connector_2_v1_1" />
        <child link="i_dip_link_v2_1" />
    </joint>
    <joint name="i_dip_pitch" type="continuous">
        <origin rpy="0 0 0" xyz="0.001 0.0 0.011" />
        <parent link="i_dip_link_v2_1" />
        <child link="i_connector_3_v1_1" />
        <axis xyz="1.0 -0.0 -0.0" />
    </joint>
    <joint name="Rigid18" type="fixed">
        <origin rpy="0 0 0" xyz="0.0015 0.0 0.015" />
        <parent link="i_connector_3_v1_1" />
        <child link="i_tip_link_v2_1" />
    </joint>
    <joint name="Rigid19" type="fixed">
        <origin rpy="0 0 0" xyz="0.0 0.0 0.0225" />
        <parent link="base_link" />
        <child link="m_mcp_yaw_link_v1_1" />
    </joint>
    <joint name="m_mcp_yaw" type="continuous">
        <origin rpy="0 0 0" xyz="-0.0 -0.002 0.018" />
        <parent link="m_mcp_yaw_link_v1_1" />
        <child link="m_mcp_pitch_link_v1_1" />
        <axis xyz="0.0 -1.0 -0.0" />
    </joint>
    <joint name="m_mcp_pitch" type="continuous">
        <origin rpy="0 0 0" xyz="0.0 -0.00725 0.041" />
        <parent link="m_mcp_pitch_link_v1_1" />
        <child link="m_connector_1_v1_1" />
        <axis xyz="-1.0 -0.0 -0.0" />
    </joint>
    <joint name="Rigid22" type="fixed">
        <origin rpy="0 0 0" xyz="0.0015 0.0 0.015" />
        <parent link="m_connector_1_v1_1" />
        <child link="m_pip_pitch_link_v2_1" />
    </joint>
    <joint name="m_pip_pitch" type="continuous">
        <origin rpy="0 0 0" xyz="-0.0015 -0.000314 0.035999" />
        <parent link="m_pip_pitch_link_v2_1" />
        <child link="m_connector_2_v1_1" />
        <axis xyz="-1.0 0.0 0.0" />
    </joint>
    <joint name="Rigid24" type="fixed">
        <origin rpy="0 0 0" xyz="0.0015 -0.000131 0.014999" />
        <parent link="m_connector_2_v1_1" />
        <child link="m_dip_link_v2_1" />
    </joint>
    <joint name="m_dip_pitch" type="continuous">
        <origin rpy="0 0 0" xyz="-0.0015 -9.6e-05 0.011" />
        <parent link="m_dip_link_v2_1" />
        <child link="m_connector_3_v1_1" />
        <axis xyz="1.0 -0.0 -0.0" />
    </joint>
    <joint name="Rigid26" type="fixed">
        <origin rpy="0 0 0" xyz="0.0015 -0.000131 0.014999" />
        <parent link="m_connector_3_v1_1" />
        <child link="m_tip_link_v2_1" />
    </joint>
    <joint name="Rigid27" type="fixed">
        <origin rpy="0 0 0" xyz="-0.0195 0.0 0.0225" />
        <parent link="base_link" />
        <child link="r_mcp_yaw_link_v1_1" />
    </joint>
    <joint name="r_mcp_yaw" type="continuous">
        <origin rpy="0 0 0" xyz="0.0 -0.002 0.018" />
        <parent link="r_mcp_yaw_link_v1_1" />
        <child link="r_mcp_pitch_link_v1_1" />
        <axis xyz="0.0 -1.0 -0.0" />
    </joint>
    <joint name="r_mcp_pitch" type="continuous">
        <origin rpy="0 0 0" xyz="0.0 -0.00725 0.041" />
        <parent link="r_mcp_pitch_link_v1_1" />
        <child link="r_connector_1_v1_1" />
        <axis xyz="-1.0 0.0 0.0" />
    </joint>
    <joint name="Rigid30" type="fixed">
        <origin rpy="0 0 0" xyz="0.0015 0.0 0.015" />
        <parent link="r_connector_1_v1_1" />
        <child link="r_pip_pitch_link_v2_1" />
    </joint>
    <joint name="r_pip_pitch" type="continuous">
        <origin rpy="0 0 0" xyz="-0.0015 0.0 0.036" />
        <parent link="r_pip_pitch_link_v2_1" />
        <child link="r_connector_2_v1_1" />
        <axis xyz="1.0 0.0 0.0" />
    </joint>
    <joint name="Rigid32" type="fixed">
        <origin rpy="0 0 0" xyz="-0.001 0.0 0.015" />
        <parent link="r_connector_2_v1_1" />
        <child link="r_dip_link_v2_1" />
    </joint>
    <joint name="r_dip_pitch" type="continuous">
        <origin rpy="0 0 0" xyz="0.001 0.0 0.011" />
        <parent link="r_dip_link_v2_1" />
        <child link="r_connector_3_v1_1" />
        <axis xyz="1.0 0.0 0.0" />
    </joint>
    <joint name="Rigid35" type="fixed">
        <origin rpy="0 0 0" xyz="-0.001 0.0 0.015" />
        <parent link="r_connector_3_v1_1" />
        <child link="r_tip_link_v2_1" />
    </joint>
    <joint name="Rigid36" type="fixed">
        <origin rpy="0 0 0" xyz="-0.039 0.0 0.0225" />
        <parent link="base_link" />
        <child link="s_mcp_yaw_link_v1_1" />
    </joint>
    <joint name="s_mcp_yaw" type="continuous">
        <origin rpy="0 0 0" xyz="0.0 -0.002 0.018" />
        <parent link="s_mcp_yaw_link_v1_1" />
        <child link="s_mcp_pitch_link_v1_1" />
        <axis xyz="-0.0 -1.0 -0.0" />
    </joint>
    <joint name="s_mcp_pitch" type="continuous">
        <origin rpy="0 0 0" xyz="0.0 -0.00725 0.041" />
        <parent link="s_mcp_pitch_link_v1_1" />
        <child link="s_connector_1_v1_1" />
        <axis xyz="-1.0 0.0 0.0" />
    </joint>
    <joint name="Rigid39" type="fixed">
        <origin rpy="0 0 0" xyz="-0.001 0.0 0.015" />
        <parent link="s_connector_1_v1_1" />
        <child link="s_pip_pitch_link_v2_1" />
    </joint>
    <joint name="s_pip_pitch" type="continuous">
        <origin rpy="0 0 0" xyz="0.001 0.0 0.036" />
        <parent link="s_pip_pitch_link_v2_1" />
        <child link="s_connector_2_v1_1" />
        <axis xyz="-1.0 -0.0 -0.0" />
    </joint>
    <joint name="Rigid41" type="fixed">
        <origin rpy="0 0 0" xyz="-0.001 0.0 0.015" />
        <parent link="s_connector_2_v1_1" />
        <child link="s_dip_link_v2_1" />
    </joint>
    <joint name="s_dip_pitch" type="continuous">
        <origin rpy="0 0 0" xyz="0.001 0.0 0.011" />
        <parent link="s_dip_link_v2_1" />
        <child link="s_connector_3_v1_1" />
        <axis xyz="1.0 -0.0 -0.0" />
    </joint>
    <joint name="Rigid43" type="fixed">
        <origin rpy="0 0 0" xyz="-0.001 0.0 0.015" />
        <parent link="s_connector_3_v1_1" />
        <child link="s_tip_link_v2_1" />
    </joint>
    <transmission name="trans_t_mcp_pitch">
        <type>transmission_interface/SimpleTransmission</type>
        <joint name="t_mcp_pitch">
            <hardwareInterface>hardware_interface/EffortJointInterface</hardwareInterface>
        </joint>
        <actuator name="t_mcp_pitch_motor">
            <hardwareInterface>hardware_interface/EffortJointInterface</hardwareInterface>
            <mechanicalReduction>1</mechanicalReduction>
        </actuator>
    </transmission>
    <transmission name="trans_t_mcp_yaw">
        <type>transmission_interface/SimpleTransmission</type>
        <joint name="t_mcp_yaw">
            <hardwareInterface>hardware_interface/EffortJointInterface</hardwareInterface>
        </joint>
        <actuator name="t_mcp_yaw_motor">
            <hardwareInterface>hardware_interface/EffortJointInterface</hardwareInterface>
            <mechanicalReduction>1</mechanicalReduction>
        </actuator>
    </transmission>
    <transmission name="trans_t_pip_pitch">
        <type>transmission_interface/SimpleTransmission</type>
        <joint name="t_pip_pitch">
            <hardwareInterface>hardware_interface/EffortJointInterface</hardwareInterface>
        </joint>
        <actuator name="t_pip_pitch_motor">
            <hardwareInterface>hardware_interface/EffortJointInterface</hardwareInterface>
            <mechanicalReduction>1</mechanicalReduction>
        </actuator>
    </transmission>
    <transmission name="trans_i_mcp_yaw">
        <type>transmission_interface/SimpleTransmission</type>
        <joint name="i_mcp_yaw">
            <hardwareInterface>hardware_interface/EffortJointInterface</hardwareInterface>
        </joint>
        <actuator name="i_mcp_yaw_motor">
            <hardwareInterface>hardware_interface/EffortJointInterface</hardwareInterface>
            <mechanicalReduction>1</mechanicalReduction>
        </actuator>
    </transmission>
    <transmission name="trans_i_mcp_pitch">
        <type>transmission_interface/SimpleTransmission</type>
        <joint name="i_mcp_pitch">
            <hardwareInterface>hardware_interface/EffortJointInterface</hardwareInterface>
        </joint>
        <actuator name="i_mcp_pitch_motor">
            <hardwareInterface>hardware_interface/EffortJointInterface</hardwareInterface>
            <mechanicalReduction>1</mechanicalReduction>
        </actuator>
    </transmission>
    <transmission name="trans_i_pip_pitch">
        <type>transmission_interface/SimpleTransmission</type>
        <joint name="i_pip_pitch">
            <hardwareInterface>hardware_interface/EffortJointInterface</hardwareInterface>
        </joint>
        <actuator name="i_pip_pitch_motor">
            <hardwareInterface>hardware_interface/EffortJointInterface</hardwareInterface>
            <mechanicalReduction>1</mechanicalReduction>
        </actuator>
    </transmission>
    <transmission name="trans_i_dip_pitch">
        <type>transmission_interface/SimpleTransmission</type>
        <joint name="i_dip_pitch">
            <hardwareInterface>hardware_interface/EffortJointInterface</hardwareInterface>
        </joint>
        <actuator name="i_dip_pitch_motor">
            <hardwareInterface>hardware_interface/EffortJointInterface</hardwareInterface>
            <mechanicalReduction>1</mechanicalReduction>
        </actuator>
    </transmission>
    <transmission name="trans_m_mcp_yaw">
        <type>transmission_interface/SimpleTransmission</type>
        <joint name="m_mcp_yaw">
            <hardwareInterface>hardware_interface/EffortJointInterface</hardwareInterface>
        </joint>
        <actuator name="m_mcp_yaw_motor">
            <hardwareInterface>hardware_interface/EffortJointInterface</hardwareInterface>
            <mechanicalReduction>1</mechanicalReduction>
        </actuator>
    </transmission>
    <transmission name="trans_m_mcp_pitch">
        <type>transmission_interface/SimpleTransmission</type>
        <joint name="m_mcp_pitch">
            <hardwareInterface>hardware_interface/EffortJointInterface</hardwareInterface>
        </joint>
        <actuator name="m_mcp_pitch_motor">
            <hardwareInterface>hardware_interface/EffortJointInterface</hardwareInterface>
            <mechanicalReduction>1</mechanicalReduction>
        </actuator>
    </transmission>
    <transmission name="trans_m_pip_pitch">
        <type>transmission_interface/SimpleTransmission</type>
        <joint name="m_pip_pitch">
            <hardwareInterface>hardware_interface/EffortJointInterface</hardwareInterface>
        </joint>
        <actuator name="m_pip_pitch_motor">
            <hardwareInterface>hardware_interface/EffortJointInterface</hardwareInterface>
            <mechanicalReduction>1</mechanicalReduction>
        </actuator>
    </transmission>
    <transmission name="trans_m_dip_pitch">
        <type>transmission_interface/SimpleTransmission</type>
        <joint name="m_dip_pitch">
            <hardwareInterface>hardware_interface/EffortJointInterface</hardwareInterface>
        </joint>
        <actuator name="m_dip_pitch_motor">
            <hardwareInterface>hardware_interface/EffortJointInterface</hardwareInterface>
            <mechanicalReduction>1</mechanicalReduction>
        </actuator>
    </transmission>
    <transmission name="trans_r_mcp_yaw">
        <type>transmission_interface/SimpleTransmission</type>
        <joint name="r_mcp_yaw">
            <hardwareInterface>hardware_interface/EffortJointInterface</hardwareInterface>
        </joint>
        <actuator name="r_mcp_yaw_motor">
            <hardwareInterface>hardware_interface/EffortJointInterface</hardwareInterface>
            <mechanicalReduction>1</mechanicalReduction>
        </actuator>
    </transmission>
    <transmission name="trans_r_mcp_pitch">
        <type>transmission_interface/SimpleTransmission</type>
        <joint name="r_mcp_pitch">
            <hardwareInterface>hardware_interface/EffortJointInterface</hardwareInterface>
        </joint>
        <actuator name="r_mcp_pitch_motor">
            <hardwareInterface>hardware_interface/EffortJointInterface</hardwareInterface>
            <mechanicalReduction>1</mechanicalReduction>
        </actuator>
    </transmission>
    <transmission name="trans_r_pip_pitch">
        <type>transmission_interface/SimpleTransmission</type>
        <joint name="r_pip_pitch">
            <hardwareInterface>hardware_interface/EffortJointInterface</hardwareInterface>
        </joint>
        <actuator name="r_pip_pitch_motor">
            <hardwareInterface>hardware_interface/EffortJointInterface</hardwareInterface>
            <mechanicalReduction>1</mechanicalReduction>
        </actuator>
    </transmission>
    <transmission name="trans_r_dip_pitch">
        <type>transmission_interface/SimpleTransmission</type>
        <joint name="r_dip_pitch">
            <hardwareInterface>hardware_interface/EffortJointInterface</hardwareInterface>
        </joint>
        <actuator name="r_dip_pitch_motor">
            <hardwareInterface>hardware_interface/EffortJointInterface</hardwareInterface>
            <mechanicalReduction>1</mechanicalReduction>
        </actuator>
    </transmission>
    <transmission name="trans_s_mcp_yaw">
        <type>transmission_interface/SimpleTransmission</type>
        <joint name="s_mcp_yaw">
            <hardwareInterface>hardware_interface/EffortJointInterface</hardwareInterface>
        </joint>
        <actuator name="s_mcp_yaw_motor">
            <hardwareInterface>hardware_interface/EffortJointInterface</hardwareInterface>
            <mechanicalReduction>1</mechanicalReduction>
        </actuator>
    </transmission>
    <transmission name="trans_s_mcp_pitch">
        <type>transmission_interface/SimpleTransmission</type>
        <joint name="s_mcp_pitch">
            <hardwareInterface>hardware_interface/EffortJointInterface</hardwareInterface>
        </joint>
        <actuator name="s_mcp_pitch_motor">
            <hardwareInterface>hardware_interface/EffortJointInterface</hardwareInterface>
            <mechanicalReduction>1</mechanicalReduction>
        </actuator>
    </transmission>
    <transmission name="trans_s_pip_pitch">
        <type>transmission_interface/SimpleTransmission</type>
        <joint name="s_pip_pitch">
            <hardwareInterface>hardware_interface/EffortJointInterface</hardwareInterface>
        </joint>
        <actuator name="s_pip_pitch_motor">
            <hardwareInterface>hardware_interface/EffortJointInterface</hardwareInterface>
            <mechanicalReduction>1</mechanicalReduction>
        </actuator>
    </transmission>
    <transmission name="trans_s_dip_pitch">
        <type>transmission_interface/SimpleTransmission</type>
        <joint name="s_dip_pitch">
            <hardwareInterface>hardware_interface/EffortJointInterface</hardwareInterface>
        </joint>
        <actuator name="s_dip_pitch_motor">
            <hardwareInterface>hardware_interface/EffortJointInterface</hardwareInterface>
            <mechanicalReduction>1</mechanicalReduction>
        </actuator>
    </transmission>
    <gazebo>
        <plugin name="gazebo_ros_control" filename="libgazebo_ros_control.so">
            <robotNamespace>/</robotNamespace>
        </plugin>
    </gazebo>
</robot>
